package com.SmellyModder.TheLostSea.common.world.overworld.village;

import java.util.List;
import java.util.Random;

import net.minecraft.block.Block;
import net.minecraft.block.BlockDoor;
import net.minecraft.block.BlockDoor.EnumHingePosition;
import net.minecraft.block.BlockSlab;
import net.minecraft.block.BlockSlab.EnumBlockHalf;
import net.minecraft.block.BlockStairs;
import net.minecraft.block.BlockStoneSlab;
import net.minecraft.block.state.IBlockState;
import net.minecraft.entity.EntityHanging;
import net.minecraft.entity.item.EntityItemFrame;
import net.minecraft.init.Blocks;
import net.minecraft.item.ItemStack;
import net.minecraft.tileentity.TileEntity;
import net.minecraft.util.EnumFacing;
import net.minecraft.util.ResourceLocation;
import net.minecraft.util.Rotation;
import net.minecraft.util.math.AxisAlignedBB;
import net.minecraft.util.math.BlockPos;
import net.minecraft.util.math.MathHelper;
import net.minecraft.world.World;
import net.minecraft.world.gen.structure.StructureBoundingBox;
import net.minecraft.world.gen.structure.StructureComponent;
import net.minecraft.world.gen.structure.StructureVillagePieces.PieceWeight;
import net.minecraft.world.gen.structure.StructureVillagePieces.Start;
import net.minecraft.world.gen.structure.StructureVillagePieces.Village;
import net.minecraftforge.fml.common.registry.VillagerRegistry.IVillageCreationHandler;
import net.minecraftforge.fml.common.registry.VillagerRegistry.VillagerProfession;


public class VillageGenNurmShop extends Village
{
	
	public VillageGenNurmShop()
	{
	}

	public VillageGenNurmShop(Start villagePiece, int par2, Random par3Random, StructureBoundingBox par4StructureBoundingBox, EnumFacing facing)
	{
		super(villagePiece, par2);
		this.setCoordBaseMode(facing);
		this.boundingBox = par4StructureBoundingBox;
	}
	
	private int groundLevel = -1;

	@Override
	public boolean addComponentParts(World world, Random rand, StructureBoundingBox box)
	{
		if(groundLevel < 0)
		{
			groundLevel = this.getAverageGroundLevel(world, box);
			if(groundLevel < 0)
				return true;
			boundingBox.offset(0, groundLevel-boundingBox.maxY + 10 - 1, 0);
		}
		
		int i = 0;
		int k = 0;
		int j = 0;
		
		this.fillWithBlocks(world, box, 0, 0, 0, 10, 9, 8, Blocks.AIR.getDefaultState(), Blocks.AIR.getDefaultState(), false);
		this.fillWithBlocks(world, box, 6, 0, 1, 9, 0, 2, Blocks.AIR.getDefaultState(), Blocks.AIR.getDefaultState(), false);
		
		world.setBlockState(new BlockPos(i + 5, j + 0, k + 2), Block.getBlockById(5).getStateFromMeta(0), 3);
		world.setBlockState(new BlockPos(i + 6, j + 0, k + 2), Block.getBlockById(5).getStateFromMeta(0), 3);
		world.setBlockState(new BlockPos(i + 7, j + 0, k + 2), Block.getBlockById(5).getStateFromMeta(0), 3);
		world.setBlockState(new BlockPos(i + 8, j + 0, k + 2), Block.getBlockById(5).getStateFromMeta(0), 3);
		world.setBlockState(new BlockPos(i + 9, j + 0, k + 2), Block.getBlockById(5).getStateFromMeta(0), 3);
		world.setBlockState(new BlockPos(i + 10, j + 0, k + 2), Block.getBlockById(5).getStateFromMeta(0), 3);
		world.setBlockState(new BlockPos(i + 11, j + 0, k + 2), Block.getBlockById(5).getStateFromMeta(0), 3);
		world.setBlockState(new BlockPos(i + 4, j + 0, k + 3), Block.getBlockById(5).getStateFromMeta(0), 3);
		world.setBlockState(new BlockPos(i + 5, j + 0, k + 3), Block.getBlockById(5).getStateFromMeta(0), 3);
		world.setBlockState(new BlockPos(i + 6, j + 0, k + 3), Block.getBlockById(5).getStateFromMeta(0), 3);
		world.setBlockState(new BlockPos(i + 7, j + 0, k + 3), Block.getBlockById(5).getStateFromMeta(0), 3);
		world.setBlockState(new BlockPos(i + 8, j + 0, k + 3), Block.getBlockById(5).getStateFromMeta(0), 3);
		world.setBlockState(new BlockPos(i + 9, j + 0, k + 3), Block.getBlockById(5).getStateFromMeta(0), 3);
		world.setBlockState(new BlockPos(i + 10, j + 0, k + 3), Block.getBlockById(5).getStateFromMeta(0), 3);
		world.setBlockState(new BlockPos(i + 11, j + 0, k + 3), Block.getBlockById(5).getStateFromMeta(0), 3);
		world.setBlockState(new BlockPos(i + 12, j + 0, k + 3), Block.getBlockById(5).getStateFromMeta(0), 3);
		world.setBlockState(new BlockPos(i + 2, j + 0, k + 4), Block.getBlockById(5).getStateFromMeta(0), 3);
		world.setBlockState(new BlockPos(i + 3, j + 0, k + 4), Block.getBlockById(5).getStateFromMeta(0), 3);
		world.setBlockState(new BlockPos(i + 4, j + 0, k + 4), Block.getBlockById(5).getStateFromMeta(0), 3);
		world.setBlockState(new BlockPos(i + 5, j + 0, k + 4), Block.getBlockById(5).getStateFromMeta(0), 3);
		world.setBlockState(new BlockPos(i + 6, j + 0, k + 4), Block.getBlockById(5).getStateFromMeta(0), 3);
		world.setBlockState(new BlockPos(i + 7, j + 0, k + 4), Block.getBlockById(5).getStateFromMeta(0), 3);
		world.setBlockState(new BlockPos(i + 8, j + 0, k + 4), Block.getBlockById(5).getStateFromMeta(0), 3);
		world.setBlockState(new BlockPos(i + 9, j + 0, k + 4), Block.getBlockById(5).getStateFromMeta(0), 3);
		world.setBlockState(new BlockPos(i + 10, j + 0, k + 4), Block.getBlockById(5).getStateFromMeta(0), 3);
		world.setBlockState(new BlockPos(i + 11, j + 0, k + 4), Block.getBlockById(5).getStateFromMeta(0), 3);
		world.setBlockState(new BlockPos(i + 12, j + 0, k + 4), Block.getBlockById(5).getStateFromMeta(0), 3);
		world.setBlockState(new BlockPos(i + 2, j + 0, k + 5), Block.getBlockById(5).getStateFromMeta(0), 3);
		world.setBlockState(new BlockPos(i + 3, j + 0, k + 5), Block.getBlockById(5).getStateFromMeta(0), 3);
		world.setBlockState(new BlockPos(i + 4, j + 0, k + 5), Block.getBlockById(5).getStateFromMeta(0), 3);
		world.setBlockState(new BlockPos(i + 5, j + 0, k + 5), Block.getBlockById(5).getStateFromMeta(0), 3);
		world.setBlockState(new BlockPos(i + 6, j + 0, k + 5), Block.getBlockById(5).getStateFromMeta(0), 3);
		world.setBlockState(new BlockPos(i + 7, j + 0, k + 5), Block.getBlockById(5).getStateFromMeta(0), 3);
		world.setBlockState(new BlockPos(i + 8, j + 0, k + 5), Block.getBlockById(5).getStateFromMeta(0), 3);
		world.setBlockState(new BlockPos(i + 9, j + 0, k + 5), Block.getBlockById(5).getStateFromMeta(0), 3);
		world.setBlockState(new BlockPos(i + 10, j + 0, k + 5), Block.getBlockById(5).getStateFromMeta(0), 3);
		world.setBlockState(new BlockPos(i + 11, j + 0, k + 5), Block.getBlockById(5).getStateFromMeta(0), 3);
		world.setBlockState(new BlockPos(i + 12, j + 0, k + 5), Block.getBlockById(5).getStateFromMeta(0), 3);
		world.setBlockState(new BlockPos(i + 2, j + 0, k + 6), Block.getBlockById(5).getStateFromMeta(0), 3);
		world.setBlockState(new BlockPos(i + 3, j + 0, k + 6), Block.getBlockById(5).getStateFromMeta(0), 3);
		world.setBlockState(new BlockPos(i + 4, j + 0, k + 6), Block.getBlockById(5).getStateFromMeta(0), 3);
		world.setBlockState(new BlockPos(i + 5, j + 0, k + 6), Block.getBlockById(5).getStateFromMeta(0), 3);
		world.setBlockState(new BlockPos(i + 6, j + 0, k + 6), Block.getBlockById(5).getStateFromMeta(0), 3);
		world.setBlockState(new BlockPos(i + 7, j + 0, k + 6), Block.getBlockById(5).getStateFromMeta(0), 3);
		world.setBlockState(new BlockPos(i + 8, j + 0, k + 6), Block.getBlockById(5).getStateFromMeta(0), 3);
		world.setBlockState(new BlockPos(i + 9, j + 0, k + 6), Block.getBlockById(5).getStateFromMeta(0), 3);
		world.setBlockState(new BlockPos(i + 10, j + 0, k + 6), Block.getBlockById(5).getStateFromMeta(0), 3);
		world.setBlockState(new BlockPos(i + 11, j + 0, k + 6), Block.getBlockById(5).getStateFromMeta(0), 3);
		world.setBlockState(new BlockPos(i + 12, j + 0, k + 6), Block.getBlockById(5).getStateFromMeta(0), 3);
		world.setBlockState(new BlockPos(i + 13, j + 0, k + 6), Block.getBlockById(5).getStateFromMeta(0), 3);
		world.setBlockState(new BlockPos(i + 2, j + 0, k + 7), Block.getBlockById(5).getStateFromMeta(0), 3);
		world.setBlockState(new BlockPos(i + 3, j + 0, k + 7), Block.getBlockById(5).getStateFromMeta(0), 3);
		world.setBlockState(new BlockPos(i + 4, j + 0, k + 7), Block.getBlockById(5).getStateFromMeta(0), 3);
		world.setBlockState(new BlockPos(i + 5, j + 0, k + 7), Block.getBlockById(5).getStateFromMeta(0), 3);
		world.setBlockState(new BlockPos(i + 6, j + 0, k + 7), Block.getBlockById(5).getStateFromMeta(0), 3);
		world.setBlockState(new BlockPos(i + 7, j + 0, k + 7), Block.getBlockById(5).getStateFromMeta(0), 3);
		world.setBlockState(new BlockPos(i + 8, j + 0, k + 7), Block.getBlockById(5).getStateFromMeta(0), 3);
		world.setBlockState(new BlockPos(i + 9, j + 0, k + 7), Block.getBlockById(5).getStateFromMeta(0), 3);
		world.setBlockState(new BlockPos(i + 10, j + 0, k + 7), Block.getBlockById(5).getStateFromMeta(0), 3);
		world.setBlockState(new BlockPos(i + 11, j + 0, k + 7), Block.getBlockById(5).getStateFromMeta(0), 3);
		world.setBlockState(new BlockPos(i + 12, j + 0, k + 7), Block.getBlockById(5).getStateFromMeta(0), 3);
		world.setBlockState(new BlockPos(i + 13, j + 0, k + 7), Block.getBlockById(5).getStateFromMeta(0), 3);
		world.setBlockState(new BlockPos(i + 14, j + 0, k + 7), Block.getBlockById(5).getStateFromMeta(0), 3);
		world.setBlockState(new BlockPos(i + 2, j + 0, k + 8), Block.getBlockById(5).getStateFromMeta(0), 3);
		world.setBlockState(new BlockPos(i + 3, j + 0, k + 8), Block.getBlockById(5).getStateFromMeta(0), 3);
		world.setBlockState(new BlockPos(i + 4, j + 0, k + 8), Block.getBlockById(17).getStateFromMeta(1), 3);
		world.setBlockState(new BlockPos(i + 5, j + 0, k + 8), Block.getBlockById(17).getStateFromMeta(5), 3);
		world.setBlockState(new BlockPos(i + 6, j + 0, k + 8), Block.getBlockById(17).getStateFromMeta(5), 3);
		world.setBlockState(new BlockPos(i + 7, j + 0, k + 8), Block.getBlockById(17).getStateFromMeta(5), 3);
		world.setBlockState(new BlockPos(i + 8, j + 0, k + 8), Block.getBlockById(17).getStateFromMeta(5), 3);
		world.setBlockState(new BlockPos(i + 9, j + 0, k + 8), Block.getBlockById(17).getStateFromMeta(5), 3);
		world.setBlockState(new BlockPos(i + 10, j + 0, k + 8), Block.getBlockById(17).getStateFromMeta(5), 3);
		world.setBlockState(new BlockPos(i + 11, j + 0, k + 8), Block.getBlockById(17).getStateFromMeta(5), 3);
		world.setBlockState(new BlockPos(i + 12, j + 0, k + 8), Block.getBlockById(17).getStateFromMeta(1), 3);
		world.setBlockState(new BlockPos(i + 13, j + 0, k + 8), Block.getBlockById(5).getStateFromMeta(0), 3);
		world.setBlockState(new BlockPos(i + 14, j + 0, k + 8), Block.getBlockById(5).getStateFromMeta(0), 3);
		world.setBlockState(new BlockPos(i + 2, j + 0, k + 9), Block.getBlockById(5).getStateFromMeta(0), 3);
		world.setBlockState(new BlockPos(i + 3, j + 0, k + 9), Block.getBlockById(5).getStateFromMeta(0), 3);
		world.setBlockState(new BlockPos(i + 4, j + 0, k + 9), Block.getBlockById(17).getStateFromMeta(9), 3);
		world.setBlockState(new BlockPos(i + 5, j + 0, k + 9), Block.getBlockById(89).getStateFromMeta(0), 3);
		world.setBlockState(new BlockPos(i + 6, j + 0, k + 9), Block.getBlockById(5).getStateFromMeta(0), 3);
		world.setBlockState(new BlockPos(i + 7, j + 0, k + 9), Block.getBlockById(5).getStateFromMeta(0), 3);
		world.setBlockState(new BlockPos(i + 8, j + 0, k + 9), Block.getBlockById(5).getStateFromMeta(0), 3);
		world.setBlockState(new BlockPos(i + 9, j + 0, k + 9), Block.getBlockById(5).getStateFromMeta(0), 3);
		world.setBlockState(new BlockPos(i + 10, j + 0, k + 9), Block.getBlockById(5).getStateFromMeta(0), 3);
		world.setBlockState(new BlockPos(i + 11, j + 0, k + 9), Block.getBlockById(89).getStateFromMeta(0), 3);
		world.setBlockState(new BlockPos(i + 12, j + 0, k + 9), Block.getBlockById(17).getStateFromMeta(9), 3);
		world.setBlockState(new BlockPos(i + 13, j + 0, k + 9), Block.getBlockById(5).getStateFromMeta(0), 3);
		world.setBlockState(new BlockPos(i + 2, j + 0, k + 10), Block.getBlockById(5).getStateFromMeta(0), 3);
		world.setBlockState(new BlockPos(i + 3, j + 0, k + 10), Block.getBlockById(5).getStateFromMeta(0), 3);
		world.setBlockState(new BlockPos(i + 4, j + 0, k + 10), Block.getBlockById(17).getStateFromMeta(9), 3);
		world.setBlockState(new BlockPos(i + 5, j + 0, k + 10), Block.getBlockById(5).getStateFromMeta(0), 3);
		world.setBlockState(new BlockPos(i + 6, j + 0, k + 10), Block.getBlockById(5).getStateFromMeta(0), 3);
		world.setBlockState(new BlockPos(i + 7, j + 0, k + 10), Block.getBlockById(5).getStateFromMeta(0), 3);
		world.setBlockState(new BlockPos(i + 8, j + 0, k + 10), Block.getBlockById(5).getStateFromMeta(0), 3);
		world.setBlockState(new BlockPos(i + 9, j + 0, k + 10), Block.getBlockById(5).getStateFromMeta(0), 3);
		world.setBlockState(new BlockPos(i + 10, j + 0, k + 10), Block.getBlockById(5).getStateFromMeta(0), 3);
		world.setBlockState(new BlockPos(i + 11, j + 0, k + 10), Block.getBlockById(5).getStateFromMeta(0), 3);
		world.setBlockState(new BlockPos(i + 12, j + 0, k + 10), Block.getBlockById(17).getStateFromMeta(9), 3);
		world.setBlockState(new BlockPos(i + 13, j + 0, k + 10), Block.getBlockById(5).getStateFromMeta(0), 3);
		world.setBlockState(new BlockPos(i + 2, j + 0, k + 11), Block.getBlockById(5).getStateFromMeta(0), 3);
		world.setBlockState(new BlockPos(i + 3, j + 0, k + 11), Block.getBlockById(5).getStateFromMeta(0), 3);
		world.setBlockState(new BlockPos(i + 4, j + 0, k + 11), Block.getBlockById(17).getStateFromMeta(9), 3);
		world.setBlockState(new BlockPos(i + 5, j + 0, k + 11), Block.getBlockById(5).getStateFromMeta(0), 3);
		world.setBlockState(new BlockPos(i + 6, j + 0, k + 11), Block.getBlockById(5).getStateFromMeta(0), 3);
		world.setBlockState(new BlockPos(i + 7, j + 0, k + 11), Block.getBlockById(5).getStateFromMeta(0), 3);
		world.setBlockState(new BlockPos(i + 8, j + 0, k + 11), Block.getBlockById(5).getStateFromMeta(0), 3);
		world.setBlockState(new BlockPos(i + 9, j + 0, k + 11), Block.getBlockById(5).getStateFromMeta(0), 3);
		world.setBlockState(new BlockPos(i + 10, j + 0, k + 11), Block.getBlockById(5).getStateFromMeta(0), 3);
		world.setBlockState(new BlockPos(i + 11, j + 0, k + 11), Block.getBlockById(5).getStateFromMeta(0), 3);
		world.setBlockState(new BlockPos(i + 12, j + 0, k + 11), Block.getBlockById(17).getStateFromMeta(9), 3);
		world.setBlockState(new BlockPos(i + 13, j + 0, k + 11), Block.getBlockById(5).getStateFromMeta(0), 3);
		world.setBlockState(new BlockPos(i + 14, j + 0, k + 11), Block.getBlockById(17).getStateFromMeta(5), 3);
		world.setBlockState(new BlockPos(i + 2, j + 0, k + 12), Block.getBlockById(5).getStateFromMeta(0), 3);
		world.setBlockState(new BlockPos(i + 3, j + 0, k + 12), Block.getBlockById(5).getStateFromMeta(0), 3);
		world.setBlockState(new BlockPos(i + 4, j + 0, k + 12), Block.getBlockById(17).getStateFromMeta(9), 3);
		world.setBlockState(new BlockPos(i + 5, j + 0, k + 12), Block.getBlockById(5).getStateFromMeta(0), 3);
		world.setBlockState(new BlockPos(i + 6, j + 0, k + 12), Block.getBlockById(5).getStateFromMeta(0), 3);
		world.setBlockState(new BlockPos(i + 7, j + 0, k + 12), Block.getBlockById(5).getStateFromMeta(0), 3);
		world.setBlockState(new BlockPos(i + 8, j + 0, k + 12), Block.getBlockById(5).getStateFromMeta(0), 3);
		world.setBlockState(new BlockPos(i + 9, j + 0, k + 12), Block.getBlockById(5).getStateFromMeta(0), 3);
		world.setBlockState(new BlockPos(i + 10, j + 0, k + 12), Block.getBlockById(5).getStateFromMeta(0), 3);
		world.setBlockState(new BlockPos(i + 11, j + 0, k + 12), Block.getBlockById(5).getStateFromMeta(0), 3);
		world.setBlockState(new BlockPos(i + 12, j + 0, k + 12), Block.getBlockById(17).getStateFromMeta(9), 3);
		world.setBlockState(new BlockPos(i + 13, j + 0, k + 12), Block.getBlockById(5).getStateFromMeta(0), 3);
		world.setBlockState(new BlockPos(i + 14, j + 0, k + 12), Block.getBlockById(17).getStateFromMeta(5), 3);
		world.setBlockState(new BlockPos(i + 2, j + 0, k + 13), Block.getBlockById(5).getStateFromMeta(0), 3);
		world.setBlockState(new BlockPos(i + 3, j + 0, k + 13), Block.getBlockById(5).getStateFromMeta(0), 3);
		world.setBlockState(new BlockPos(i + 4, j + 0, k + 13), Block.getBlockById(17).getStateFromMeta(9), 3);
		world.setBlockState(new BlockPos(i + 5, j + 0, k + 13), Block.getBlockById(5).getStateFromMeta(0), 3);
		world.setBlockState(new BlockPos(i + 6, j + 0, k + 13), Block.getBlockById(5).getStateFromMeta(0), 3);
		world.setBlockState(new BlockPos(i + 7, j + 0, k + 13), Block.getBlockById(5).getStateFromMeta(0), 3);
		world.setBlockState(new BlockPos(i + 8, j + 0, k + 13), Block.getBlockById(5).getStateFromMeta(0), 3);
		world.setBlockState(new BlockPos(i + 9, j + 0, k + 13), Block.getBlockById(5).getStateFromMeta(0), 3);
		world.setBlockState(new BlockPos(i + 10, j + 0, k + 13), Block.getBlockById(5).getStateFromMeta(0), 3);
		world.setBlockState(new BlockPos(i + 11, j + 0, k + 13), Block.getBlockById(5).getStateFromMeta(0), 3);
		world.setBlockState(new BlockPos(i + 12, j + 0, k + 13), Block.getBlockById(17).getStateFromMeta(9), 3);
		world.setBlockState(new BlockPos(i + 13, j + 0, k + 13), Block.getBlockById(5).getStateFromMeta(0), 3);
		world.setBlockState(new BlockPos(i + 2, j + 0, k + 14), Block.getBlockById(5).getStateFromMeta(0), 3);
		world.setBlockState(new BlockPos(i + 3, j + 0, k + 14), Block.getBlockById(5).getStateFromMeta(0), 3);
		world.setBlockState(new BlockPos(i + 4, j + 0, k + 14), Block.getBlockById(17).getStateFromMeta(9), 3);
		world.setBlockState(new BlockPos(i + 5, j + 0, k + 14), Block.getBlockById(5).getStateFromMeta(0), 3);
		world.setBlockState(new BlockPos(i + 6, j + 0, k + 14), Block.getBlockById(5).getStateFromMeta(0), 3);
		world.setBlockState(new BlockPos(i + 7, j + 0, k + 14), Block.getBlockById(5).getStateFromMeta(0), 3);
		world.setBlockState(new BlockPos(i + 8, j + 0, k + 14), Block.getBlockById(5).getStateFromMeta(0), 3);
		world.setBlockState(new BlockPos(i + 9, j + 0, k + 14), Block.getBlockById(5).getStateFromMeta(0), 3);
		world.setBlockState(new BlockPos(i + 10, j + 0, k + 14), Block.getBlockById(5).getStateFromMeta(0), 3);
		world.setBlockState(new BlockPos(i + 11, j + 0, k + 14), Block.getBlockById(5).getStateFromMeta(0), 3);
		world.setBlockState(new BlockPos(i + 12, j + 0, k + 14), Block.getBlockById(17).getStateFromMeta(9), 3);
		world.setBlockState(new BlockPos(i + 13, j + 0, k + 14), Block.getBlockById(5).getStateFromMeta(0), 3);
		world.setBlockState(new BlockPos(i + 3, j + 0, k + 15), Block.getBlockById(5).getStateFromMeta(0), 3);
		world.setBlockState(new BlockPos(i + 4, j + 0, k + 15), Block.getBlockById(17).getStateFromMeta(9), 3);
		world.setBlockState(new BlockPos(i + 5, j + 0, k + 15), Block.getBlockById(89).getStateFromMeta(0), 3);
		world.setBlockState(new BlockPos(i + 6, j + 0, k + 15), Block.getBlockById(5).getStateFromMeta(0), 3);
		world.setBlockState(new BlockPos(i + 7, j + 0, k + 15), Block.getBlockById(5).getStateFromMeta(0), 3);
		world.setBlockState(new BlockPos(i + 8, j + 0, k + 15), Block.getBlockById(5).getStateFromMeta(0), 3);
		world.setBlockState(new BlockPos(i + 9, j + 0, k + 15), Block.getBlockById(5).getStateFromMeta(0), 3);
		world.setBlockState(new BlockPos(i + 10, j + 0, k + 15), Block.getBlockById(5).getStateFromMeta(0), 3);
		world.setBlockState(new BlockPos(i + 11, j + 0, k + 15), Block.getBlockById(89).getStateFromMeta(0), 3);
		world.setBlockState(new BlockPos(i + 12, j + 0, k + 15), Block.getBlockById(17).getStateFromMeta(9), 3);
		world.setBlockState(new BlockPos(i + 13, j + 0, k + 15), Block.getBlockById(5).getStateFromMeta(0), 3);
		world.setBlockState(new BlockPos(i + 3, j + 0, k + 16), Block.getBlockById(5).getStateFromMeta(0), 3);
		world.setBlockState(new BlockPos(i + 4, j + 0, k + 16), Block.getBlockById(17).getStateFromMeta(1), 3);
		world.setBlockState(new BlockPos(i + 5, j + 0, k + 16), Block.getBlockById(17).getStateFromMeta(5), 3);
		world.setBlockState(new BlockPos(i + 6, j + 0, k + 16), Block.getBlockById(17).getStateFromMeta(5), 3);
		world.setBlockState(new BlockPos(i + 7, j + 0, k + 16), Block.getBlockById(17).getStateFromMeta(5), 3);
		world.setBlockState(new BlockPos(i + 8, j + 0, k + 16), Block.getBlockById(17).getStateFromMeta(5), 3);
		world.setBlockState(new BlockPos(i + 9, j + 0, k + 16), Block.getBlockById(17).getStateFromMeta(5), 3);
		world.setBlockState(new BlockPos(i + 10, j + 0, k + 16), Block.getBlockById(17).getStateFromMeta(5), 3);
		world.setBlockState(new BlockPos(i + 11, j + 0, k + 16), Block.getBlockById(17).getStateFromMeta(5), 3);
		world.setBlockState(new BlockPos(i + 12, j + 0, k + 16), Block.getBlockById(17).getStateFromMeta(1), 3);
		world.setBlockState(new BlockPos(i + 7, j + 0, k + 17), Block.getBlockById(5).getStateFromMeta(0), 3);
		world.setBlockState(new BlockPos(i + 8, j + 0, k + 17), Block.getBlockById(5).getStateFromMeta(0), 3);
		world.setBlockState(new BlockPos(i + 9, j + 0, k + 17), Block.getBlockById(5).getStateFromMeta(0), 3);
		world.setBlockState(new BlockPos(i + 10, j + 0, k + 17), Block.getBlockById(5).getStateFromMeta(0), 3);
		world.setBlockState(new BlockPos(i + 11, j + 0, k + 17), Block.getBlockById(5).getStateFromMeta(0), 3);
		world.setBlockState(new BlockPos(i + 12, j + 0, k + 17), Block.getBlockById(5).getStateFromMeta(0), 3);
		world.setBlockState(new BlockPos(i + 9, j + 0, k + 18), Block.getBlockById(5).getStateFromMeta(0), 3);
		world.setBlockState(new BlockPos(i + 10, j + 0, k + 18), Block.getBlockById(5).getStateFromMeta(0), 3);
		world.setBlockState(new BlockPos(i + 5, j + 1, k + 1), Block.getBlockById(5).getStateFromMeta(0), 3);
		world.setBlockState(new BlockPos(i + 6, j + 1, k + 1), Block.getBlockById(5).getStateFromMeta(0), 3);
		world.setBlockState(new BlockPos(i + 7, j + 1, k + 1), Block.getBlockById(17).getStateFromMeta(1), 3);
		world.setBlockState(new BlockPos(i + 8, j + 1, k + 1), Block.getBlockById(5).getStateFromMeta(0), 3);
		world.setBlockState(new BlockPos(i + 9, j + 1, k + 1), Block.getBlockById(5).getStateFromMeta(0), 3);
		world.setBlockState(new BlockPos(i + 10, j + 1, k + 1), Block.getBlockById(17).getStateFromMeta(1), 3);
		world.setBlockState(new BlockPos(i + 11, j + 1, k + 1), Block.getBlockById(5).getStateFromMeta(0), 3);
		world.setBlockState(new BlockPos(i + 12, j + 1, k + 1), Block.getBlockById(5).getStateFromMeta(0), 3);
		world.setBlockState(new BlockPos(i + 4, j + 1, k + 2), Block.getBlockById(17).getStateFromMeta(5), 3);
		world.setBlockState(new BlockPos(i + 5, j + 1, k + 2), Block.getBlockById(57).getStateFromMeta(0), 3);
		world.setBlockState(new BlockPos(i + 6, j + 1, k + 2), Block.getBlockById(57).getStateFromMeta(0), 3);
		world.setBlockState(new BlockPos(i + 7, j + 1, k + 2), Block.getBlockById(17).getStateFromMeta(9), 3);
		world.setBlockState(new BlockPos(i + 10, j + 1, k + 2), Block.getBlockById(17).getStateFromMeta(9), 3);
		world.setBlockState(new BlockPos(i + 12, j + 1, k + 2), Block.getBlockById(5).getStateFromMeta(0), 3);
		world.setBlockState(new BlockPos(i + 1, j + 1, k + 3), Block.getBlockById(17).getStateFromMeta(1), 3);
		world.setBlockState(new BlockPos(i + 2, j + 1, k + 3), Block.getBlockById(17).getStateFromMeta(5), 3);
		world.setBlockState(new BlockPos(i + 3, j + 1, k + 3), Block.getBlockById(17).getStateFromMeta(5), 3);
		world.setBlockState(new BlockPos(i + 4, j + 1, k + 3), Block.getBlockById(47).getStateFromMeta(0), 3);
		world.setBlockState(new BlockPos(i + 5, j + 1, k + 3), Block.getBlockById(57).getStateFromMeta(0), 3);
		world.setBlockState(new BlockPos(i + 13, j + 1, k + 3), Block.getBlockById(5).getStateFromMeta(0), 3);
		world.setBlockState(new BlockPos(i + 1, j + 1, k + 4), Block.getBlockById(5).getStateFromMeta(0), 3);
		world.setBlockState(new BlockPos(i + 13, j + 1, k + 4), Block.getBlockById(5).getStateFromMeta(0), 3);
		world.setBlockState(new BlockPos(i + 1, j + 1, k + 5), Block.getBlockById(5).getStateFromMeta(0), 3);
		world.setBlockState(new BlockPos(i + 13, j + 1, k + 5), Block.getBlockById(5).getStateFromMeta(0), 3);
		world.setBlockState(new BlockPos(i + 14, j + 1, k + 5), Block.getBlockById(5).getStateFromMeta(0), 3);
		world.setBlockState(new BlockPos(i + 1, j + 1, k + 6), Block.getBlockById(5).getStateFromMeta(0), 3);
		world.setBlockState(new BlockPos(i + 2, j + 1, k + 6), Block.getBlockById(17).getStateFromMeta(1), 3);
		world.setBlockState(new BlockPos(i + 3, j + 1, k + 6), Block.getBlockById(188).getStateFromMeta(0), 3);
		world.setBlockState(new BlockPos(i + 4, j + 1, k + 6), Block.getBlockById(188).getStateFromMeta(0), 3);
		world.setBlockState(new BlockPos(i + 5, j + 1, k + 6), Block.getBlockById(17).getStateFromMeta(1), 3);
		world.setBlockState(new BlockPos(i + 6, j + 1, k + 6), Block.getBlockById(188).getStateFromMeta(0), 3);
		world.setBlockState(new BlockPos(i + 7, j + 1, k + 6), Block.getBlockById(188).getStateFromMeta(0), 3);
		world.setBlockState(new BlockPos(i + 8, j + 1, k + 6), Block.getBlockById(188).getStateFromMeta(0), 3);
		world.setBlockState(new BlockPos(i + 9, j + 1, k + 6), Block.getBlockById(188).getStateFromMeta(0), 3);
		world.setBlockState(new BlockPos(i + 10, j + 1, k + 6), Block.getBlockById(17).getStateFromMeta(1), 3);
		world.setBlockState(new BlockPos(i + 11, j + 1, k + 6), Block.getBlockById(188).getStateFromMeta(0), 3);
		world.setBlockState(new BlockPos(i + 12, j + 1, k + 6), Block.getBlockById(188).getStateFromMeta(0), 3);
		world.setBlockState(new BlockPos(i + 13, j + 1, k + 6), Block.getBlockById(17).getStateFromMeta(1), 3);
		world.setBlockState(new BlockPos(i + 14, j + 1, k + 6), Block.getBlockById(5).getStateFromMeta(0), 3);
		world.setBlockState(new BlockPos(i + 1, j + 1, k + 7), Block.getBlockById(5).getStateFromMeta(0), 3);
		world.setBlockState(new BlockPos(i + 15, j + 1, k + 7), Block.getBlockById(5).getStateFromMeta(0), 3);
		world.setBlockState(new BlockPos(i + 16, j + 1, k + 7), Block.getBlockById(4).getStateFromMeta(0), 3);
		world.setBlockState(new BlockPos(i + 1, j + 1, k + 8), Block.getBlockById(5).getStateFromMeta(0), 3);
		world.setBlockState(new BlockPos(i + 15, j + 1, k + 8), Block.getBlockById(17).getStateFromMeta(1), 3);
		world.setBlockState(new BlockPos(i + 1, j + 1, k + 9), Block.getBlockById(5).getStateFromMeta(0), 3);
		world.setBlockState(new BlockPos(i + 2, j + 1, k + 9), Block.getBlockById(47).getStateFromMeta(0), 3);
		world.setBlockState(new BlockPos(i + 6, j + 1, k + 9), Block.getBlockById(171).getStateFromMeta(15), 3);
		world.setBlockState(new BlockPos(i + 10, j + 1, k + 9), Block.getBlockById(171).getStateFromMeta(15), 3);
		world.setBlockState(new BlockPos(i + 14, j + 1, k + 9), Block.getBlockById(5).getStateFromMeta(0), 3);
		world.setBlockState(new BlockPos(i + 1, j + 1, k + 10), Block.getBlockById(5).getStateFromMeta(0), 3);
		world.setBlockState(new BlockPos(i + 2, j + 1, k + 10), Block.getBlockById(17).getStateFromMeta(9), 3);
		world.setBlockState(new BlockPos(i + 5, j + 1, k + 10), Block.getBlockById(171).getStateFromMeta(15), 3);
		world.setBlockState(new BlockPos(i + 6, j + 1, k + 10), Block.getBlockById(171).getStateFromMeta(0), 3);
		world.setBlockState(new BlockPos(i + 7, j + 1, k + 10), Block.getBlockById(171).getStateFromMeta(14), 3);
		world.setBlockState(new BlockPos(i + 9, j + 1, k + 10), Block.getBlockById(171).getStateFromMeta(14), 3);
		world.setBlockState(new BlockPos(i + 10, j + 1, k + 10), Block.getBlockById(171).getStateFromMeta(0), 3);
		world.setBlockState(new BlockPos(i + 11, j + 1, k + 10), Block.getBlockById(171).getStateFromMeta(15), 3);
		world.setBlockState(new BlockPos(i + 14, j + 1, k + 10), Block.getBlockById(5).getStateFromMeta(0), 3);
		world.setBlockState(new BlockPos(i + 1, j + 1, k + 11), Block.getBlockById(5).getStateFromMeta(0), 3);
		world.setBlockState(new BlockPos(i + 2, j + 1, k + 11), Block.getBlockById(47).getStateFromMeta(0), 3);
		world.setBlockState(new BlockPos(i + 6, j + 1, k + 11), Block.getBlockById(171).getStateFromMeta(14), 3);
		world.setBlockState(new BlockPos(i + 7, j + 1, k + 11), Block.getBlockById(171).getStateFromMeta(15), 3);
		world.setBlockState(new BlockPos(i + 8, j + 1, k + 11), Block.getBlockById(171).getStateFromMeta(0), 3);
		world.setBlockState(new BlockPos(i + 9, j + 1, k + 11), Block.getBlockById(171).getStateFromMeta(15), 3);
		world.setBlockState(new BlockPos(i + 10, j + 1, k + 11), Block.getBlockById(171).getStateFromMeta(14), 3);
		world.setBlockState(new BlockPos(i + 14, j + 1, k + 11), Block.getBlockById(193).getStateFromMeta(6), 3);
		world.setBlockState(new BlockPos(i + 1, j + 1, k + 12), Block.getBlockById(5).getStateFromMeta(0), 3);
		world.setBlockState(new BlockPos(i + 2, j + 1, k + 12), Block.getBlockById(17).getStateFromMeta(5), 3);
		world.setBlockState(new BlockPos(i + 7, j + 1, k + 12), Block.getBlockById(171).getStateFromMeta(0), 3);
		world.setBlockState(new BlockPos(i + 8, j + 1, k + 12), Block.getBlockById(171).getStateFromMeta(15), 3);
		world.setBlockState(new BlockPos(i + 9, j + 1, k + 12), Block.getBlockById(171).getStateFromMeta(0), 3);
		world.setBlockState(new BlockPos(i + 14, j + 1, k + 12), Block.getBlockById(193).getStateFromMeta(6), 3);
		world.setBlockState(new BlockPos(i + 1, j + 1, k + 13), Block.getBlockById(5).getStateFromMeta(0), 3);
		world.setBlockState(new BlockPos(i + 2, j + 1, k + 13), Block.getBlockById(47).getStateFromMeta(0), 3);
		world.setBlockState(new BlockPos(i + 6, j + 1, k + 13), Block.getBlockById(171).getStateFromMeta(14), 3);
		world.setBlockState(new BlockPos(i + 7, j + 1, k + 13), Block.getBlockById(171).getStateFromMeta(15), 3);
		world.setBlockState(new BlockPos(i + 8, j + 1, k + 13), Block.getBlockById(171).getStateFromMeta(0), 3);
		world.setBlockState(new BlockPos(i + 9, j + 1, k + 13), Block.getBlockById(171).getStateFromMeta(15), 3);
		world.setBlockState(new BlockPos(i + 10, j + 1, k + 13), Block.getBlockById(171).getStateFromMeta(14), 3);
		world.setBlockState(new BlockPos(i + 14, j + 1, k + 13), Block.getBlockById(5).getStateFromMeta(0), 3);
		world.setBlockState(new BlockPos(i + 15, j + 1, k + 13), Block.getBlockById(48).getStateFromMeta(0), 3);
		world.setBlockState(new BlockPos(i + 1, j + 1, k + 14), Block.getBlockById(5).getStateFromMeta(0), 3);
		world.setBlockState(new BlockPos(i + 5, j + 1, k + 14), Block.getBlockById(171).getStateFromMeta(15), 3);
		world.setBlockState(new BlockPos(i + 6, j + 1, k + 14), Block.getBlockById(171).getStateFromMeta(0), 3);
		world.setBlockState(new BlockPos(i + 7, j + 1, k + 14), Block.getBlockById(171).getStateFromMeta(14), 3);
		world.setBlockState(new BlockPos(i + 9, j + 1, k + 14), Block.getBlockById(171).getStateFromMeta(14), 3);
		world.setBlockState(new BlockPos(i + 10, j + 1, k + 14), Block.getBlockById(171).getStateFromMeta(0), 3);
		world.setBlockState(new BlockPos(i + 11, j + 1, k + 14), Block.getBlockById(171).getStateFromMeta(15), 3);
		world.setBlockState(new BlockPos(i + 14, j + 1, k + 14), Block.getBlockById(5).getStateFromMeta(0), 3);
		world.setBlockState(new BlockPos(i + 15, j + 1, k + 14), Block.getBlockById(98).getStateFromMeta(3), 3);
		world.setBlockState(new BlockPos(i + 1, j + 1, k + 15), Block.getBlockById(17).getStateFromMeta(9), 3);
		world.setBlockState(new BlockPos(i + 2, j + 1, k + 15), Block.getBlockById(5).getStateFromMeta(0), 3);
		world.setBlockState(new BlockPos(i + 3, j + 1, k + 15), Block.getBlockById(5).getStateFromMeta(0), 3);
		world.setBlockState(new BlockPos(i + 6, j + 1, k + 15), Block.getBlockById(171).getStateFromMeta(15), 3);
		world.setBlockState(new BlockPos(i + 10, j + 1, k + 15), Block.getBlockById(171).getStateFromMeta(15), 3);
		world.setBlockState(new BlockPos(i + 14, j + 1, k + 15), Block.getBlockById(5).getStateFromMeta(0), 3);
		world.setBlockState(new BlockPos(i + 15, j + 1, k + 15), Block.getBlockById(17).getStateFromMeta(1), 3);
		world.setBlockState(new BlockPos(i + 2, j + 1, k + 16), Block.getBlockById(5).getStateFromMeta(0), 3);
		world.setBlockState(new BlockPos(i + 3, j + 1, k + 16), Block.getBlockById(5).getStateFromMeta(0), 3);
		world.setBlockState(new BlockPos(i + 4, j + 1, k + 16), Block.getBlockById(5).getStateFromMeta(0), 3);
		world.setBlockState(new BlockPos(i + 5, j + 1, k + 16), Block.getBlockById(84).getStateFromMeta(1), 3);
		world.setBlockState(new BlockPos(i + 13, j + 1, k + 16), Block.getBlockById(5).getStateFromMeta(0), 3);
		world.setBlockState(new BlockPos(i + 16, j + 1, k + 16), Block.getBlockById(91).getStateFromMeta(3), 3);
		world.setBlockState(new BlockPos(i + 3, j + 1, k + 17), Block.getBlockById(5).getStateFromMeta(0), 3);
		world.setBlockState(new BlockPos(i + 4, j + 1, k + 17), Block.getBlockById(5).getStateFromMeta(0), 3);
		world.setBlockState(new BlockPos(i + 5, j + 1, k + 17), Block.getBlockById(5).getStateFromMeta(0), 3);
		world.setBlockState(new BlockPos(i + 6, j + 1, k + 17), Block.getBlockById(5).getStateFromMeta(0), 3);
		world.setBlockState(new BlockPos(i + 12, j + 1, k + 17), Block.getBlockById(168).getStateFromMeta(2), 3);
		world.setBlockState(new BlockPos(i + 13, j + 1, k + 17), Block.getBlockById(5).getStateFromMeta(0), 3);
		world.setBlockState(new BlockPos(i + 7, j + 1, k + 18), Block.getBlockById(5).getStateFromMeta(0), 3);
		world.setBlockState(new BlockPos(i + 8, j + 1, k + 18), Block.getBlockById(5).getStateFromMeta(0), 3);
		world.setBlockState(new BlockPos(i + 11, j + 1, k + 18), Block.getBlockById(5).getStateFromMeta(0), 3);
		world.setBlockState(new BlockPos(i + 12, j + 1, k + 18), Block.getBlockById(5).getStateFromMeta(0), 3);
		world.setBlockState(new BlockPos(i + 9, j + 1, k + 19), Block.getBlockById(5).getStateFromMeta(0), 3);
		world.setBlockState(new BlockPos(i + 10, j + 1, k + 19), Block.getBlockById(5).getStateFromMeta(0), 3);
		world.setBlockState(new BlockPos(i + 5, j + 2, k + 1), Block.getBlockById(5).getStateFromMeta(0), 3);
		world.setBlockState(new BlockPos(i + 6, j + 2, k + 1), Block.getBlockById(5).getStateFromMeta(0), 3);
		world.setBlockState(new BlockPos(i + 7, j + 2, k + 1), Block.getBlockById(17).getStateFromMeta(1), 3);
		world.setBlockState(new BlockPos(i + 8, j + 2, k + 1), Block.getBlockById(5).getStateFromMeta(0), 3);
		world.setBlockState(new BlockPos(i + 9, j + 2, k + 1), Block.getBlockById(5).getStateFromMeta(0), 3);
		world.setBlockState(new BlockPos(i + 10, j + 2, k + 1), Block.getBlockById(17).getStateFromMeta(1), 3);
		world.setBlockState(new BlockPos(i + 11, j + 2, k + 1), Block.getBlockById(5).getStateFromMeta(0), 3);
		world.setBlockState(new BlockPos(i + 12, j + 2, k + 1), Block.getBlockById(5).getStateFromMeta(0), 3);
		world.setBlockState(new BlockPos(i + 13, j + 2, k + 1), Block.getBlockById(5).getStateFromMeta(0), 3);
		world.setBlockState(new BlockPos(i + 4, j + 2, k + 2), Block.getBlockById(5).getStateFromMeta(0), 3);
		world.setBlockState(new BlockPos(i + 5, j + 2, k + 2), Block.getBlockById(57).getStateFromMeta(0), 3);
		world.setBlockState(new BlockPos(i + 12, j + 2, k + 2), Block.getBlockById(65).getStateFromMeta(3), 3);
		world.setBlockState(new BlockPos(i + 13, j + 2, k + 2), Block.getBlockById(5).getStateFromMeta(0), 3);
		world.setBlockState(new BlockPos(i + 1, j + 2, k + 3), Block.getBlockById(17).getStateFromMeta(1), 3);
		world.setBlockState(new BlockPos(i + 2, j + 2, k + 3), Block.getBlockById(5).getStateFromMeta(0), 3);
		world.setBlockState(new BlockPos(i + 3, j + 2, k + 3), Block.getBlockById(5).getStateFromMeta(0), 3);
		world.setBlockState(new BlockPos(i + 4, j + 2, k + 3), Block.getBlockById(47).getStateFromMeta(0), 3);
		world.setBlockState(new BlockPos(i + 14, j + 2, k + 3), Block.getBlockById(5).getStateFromMeta(0), 3);
		world.setBlockState(new BlockPos(i + 1, j + 2, k + 4), Block.getBlockById(5).getStateFromMeta(0), 3);
		world.setBlockState(new BlockPos(i + 14, j + 2, k + 4), Block.getBlockById(5).getStateFromMeta(0), 3);
		world.setBlockState(new BlockPos(i + 1, j + 2, k + 5), Block.getBlockById(5).getStateFromMeta(0), 3);
		world.setBlockState(new BlockPos(i + 14, j + 2, k + 5), Block.getBlockById(5).getStateFromMeta(0), 3);
		world.setBlockState(new BlockPos(i + 1, j + 2, k + 6), Block.getBlockById(5).getStateFromMeta(0), 3);
		world.setBlockState(new BlockPos(i + 2, j + 2, k + 6), Block.getBlockById(126).getStateFromMeta(1), 3);
		world.setBlockState(new BlockPos(i + 5, j + 2, k + 6), Block.getBlockById(126).getStateFromMeta(1), 3);
		world.setBlockState(new BlockPos(i + 10, j + 2, k + 6), Block.getBlockById(126).getStateFromMeta(1), 3);
		world.setBlockState(new BlockPos(i + 13, j + 2, k + 6), Block.getBlockById(126).getStateFromMeta(1), 3);
		world.setBlockState(new BlockPos(i + 15, j + 2, k + 6), Block.getBlockById(5).getStateFromMeta(0), 3);
		world.setBlockState(new BlockPos(i + 1, j + 2, k + 7), Block.getBlockById(5).getStateFromMeta(0), 3);
		world.setBlockState(new BlockPos(i + 15, j + 2, k + 7), Block.getBlockById(5).getStateFromMeta(0), 3);
		world.setBlockState(new BlockPos(i + 16, j + 2, k + 7), Block.getBlockById(140).getStateFromMeta(0), 3);
		world.setBlockState(new BlockPos(i + 1, j + 2, k + 8), Block.getBlockById(5).getStateFromMeta(0), 3);
		world.setBlockState(new BlockPos(i + 15, j + 2, k + 8), Block.getBlockById(17).getStateFromMeta(1), 3);
		world.setBlockState(new BlockPos(i + 1, j + 2, k + 9), Block.getBlockById(5).getStateFromMeta(0), 3);
		world.setBlockState(new BlockPos(i + 2, j + 2, k + 9), Block.getBlockById(47).getStateFromMeta(0), 3);
		world.setBlockState(new BlockPos(i + 14, j + 2, k + 9), Block.getBlockById(5).getStateFromMeta(0), 3);
		world.setBlockState(new BlockPos(i + 1, j + 2, k + 10), Block.getBlockById(5).getStateFromMeta(0), 3);
		world.setBlockState(new BlockPos(i + 2, j + 2, k + 10), Block.getBlockById(140).getStateFromMeta(0), 3);
		world.setBlockState(new BlockPos(i + 14, j + 2, k + 10), Block.getBlockById(5).getStateFromMeta(0), 3);
		world.setBlockState(new BlockPos(i + 1, j + 2, k + 11), Block.getBlockById(5).getStateFromMeta(0), 3);
		world.setBlockState(new BlockPos(i + 2, j + 2, k + 11), Block.getBlockById(47).getStateFromMeta(0), 3);
		world.setBlockState(new BlockPos(i + 14, j + 2, k + 11), Block.getBlockById(193).getStateFromMeta(9), 3);
		world.setBlockState(new BlockPos(i + 1, j + 2, k + 12), Block.getBlockById(5).getStateFromMeta(0), 3);
		world.setBlockState(new BlockPos(i + 2, j + 2, k + 12), Block.getBlockById(130).getStateFromMeta(5), 3);
		world.setBlockState(new BlockPos(i + 14, j + 2, k + 12), Block.getBlockById(193).getStateFromMeta(8), 3);
		world.setBlockState(new BlockPos(i + 1, j + 2, k + 13), Block.getBlockById(5).getStateFromMeta(0), 3);
		world.setBlockState(new BlockPos(i + 2, j + 2, k + 13), Block.getBlockById(47).getStateFromMeta(0), 3);
		world.setBlockState(new BlockPos(i + 14, j + 2, k + 13), Block.getBlockById(5).getStateFromMeta(0), 3);
		world.setBlockState(new BlockPos(i + 15, j + 2, k + 13), Block.getBlockById(140).getStateFromMeta(0), 3);
		world.setBlockState(new BlockPos(i + 1, j + 2, k + 14), Block.getBlockById(5).getStateFromMeta(0), 3);
		world.setBlockState(new BlockPos(i + 14, j + 2, k + 14), Block.getBlockById(5).getStateFromMeta(0), 3);
		world.setBlockState(new BlockPos(i + 1, j + 2, k + 15), Block.getBlockById(5).getStateFromMeta(0), 3);
		world.setBlockState(new BlockPos(i + 15, j + 2, k + 15), Block.getBlockById(17).getStateFromMeta(1), 3);
		world.setBlockState(new BlockPos(i + 1, j + 2, k + 16), Block.getBlockById(17).getStateFromMeta(9), 3);
		world.setBlockState(new BlockPos(i + 2, j + 2, k + 16), Block.getBlockById(5).getStateFromMeta(0), 3);
		world.setBlockState(new BlockPos(i + 3, j + 2, k + 16), Block.getBlockById(5).getStateFromMeta(0), 3);
		world.setBlockState(new BlockPos(i + 14, j + 2, k + 16), Block.getBlockById(5).getStateFromMeta(0), 3);
		world.setBlockState(new BlockPos(i + 2, j + 2, k + 17), Block.getBlockById(5).getStateFromMeta(0), 3);
		world.setBlockState(new BlockPos(i + 3, j + 2, k + 17), Block.getBlockById(5).getStateFromMeta(0), 3);
		world.setBlockState(new BlockPos(i + 4, j + 2, k + 17), Block.getBlockById(5).getStateFromMeta(0), 3);
		world.setBlockState(new BlockPos(i + 5, j + 2, k + 17), Block.getBlockById(5).getStateFromMeta(0), 3);
		world.setBlockState(new BlockPos(i + 13, j + 2, k + 17), Block.getBlockById(19).getStateFromMeta(0), 3);
		world.setBlockState(new BlockPos(i + 14, j + 2, k + 17), Block.getBlockById(5).getStateFromMeta(0), 3);
		world.setBlockState(new BlockPos(i + 6, j + 2, k + 18), Block.getBlockById(5).getStateFromMeta(0), 3);
		world.setBlockState(new BlockPos(i + 12, j + 2, k + 18), Block.getBlockById(168).getStateFromMeta(1), 3);
		world.setBlockState(new BlockPos(i + 13, j + 2, k + 18), Block.getBlockById(5).getStateFromMeta(0), 3);
		world.setBlockState(new BlockPos(i + 7, j + 2, k + 19), Block.getBlockById(5).getStateFromMeta(0), 3);
		world.setBlockState(new BlockPos(i + 8, j + 2, k + 19), Block.getBlockById(5).getStateFromMeta(0), 3);
		world.setBlockState(new BlockPos(i + 11, j + 2, k + 19), Block.getBlockById(5).getStateFromMeta(0), 3);
		world.setBlockState(new BlockPos(i + 12, j + 2, k + 19), Block.getBlockById(5).getStateFromMeta(0), 3);
		world.setBlockState(new BlockPos(i + 9, j + 2, k + 20), Block.getBlockById(5).getStateFromMeta(0), 3);
		world.setBlockState(new BlockPos(i + 10, j + 2, k + 20), Block.getBlockById(5).getStateFromMeta(0), 3);
		world.setBlockState(new BlockPos(i + 9, j + 2, k + 21), Block.getBlockById(5).getStateFromMeta(0), 3);
		world.setBlockState(new BlockPos(i + 10, j + 2, k + 21), Block.getBlockById(5).getStateFromMeta(0), 3);
		world.setBlockState(new BlockPos(i + 5, j + 3, k + 1), Block.getBlockById(5).getStateFromMeta(0), 3);
		world.setBlockState(new BlockPos(i + 6, j + 3, k + 1), Block.getBlockById(5).getStateFromMeta(0), 3);
		world.setBlockState(new BlockPos(i + 7, j + 3, k + 1), Block.getBlockById(17).getStateFromMeta(1), 3);
		world.setBlockState(new BlockPos(i + 8, j + 3, k + 1), Block.getBlockById(5).getStateFromMeta(0), 3);
		world.setBlockState(new BlockPos(i + 9, j + 3, k + 1), Block.getBlockById(5).getStateFromMeta(0), 3);
		world.setBlockState(new BlockPos(i + 10, j + 3, k + 1), Block.getBlockById(17).getStateFromMeta(1), 3);
		world.setBlockState(new BlockPos(i + 11, j + 3, k + 1), Block.getBlockById(5).getStateFromMeta(0), 3);
		world.setBlockState(new BlockPos(i + 12, j + 3, k + 1), Block.getBlockById(5).getStateFromMeta(0), 3);
		world.setBlockState(new BlockPos(i + 13, j + 3, k + 1), Block.getBlockById(5).getStateFromMeta(0), 3);
		world.setBlockState(new BlockPos(i + 14, j + 3, k + 1), Block.getBlockById(5).getStateFromMeta(0), 3);
		world.setBlockState(new BlockPos(i + 4, j + 3, k + 2), Block.getBlockById(5).getStateFromMeta(0), 3);
		world.setBlockState(new BlockPos(i + 12, j + 3, k + 2), Block.getBlockById(65).getStateFromMeta(3), 3);
		world.setBlockState(new BlockPos(i + 14, j + 3, k + 2), Block.getBlockById(5).getStateFromMeta(0), 3);
		world.setBlockState(new BlockPos(i + 1, j + 3, k + 3), Block.getBlockById(17).getStateFromMeta(1), 3);
		world.setBlockState(new BlockPos(i + 2, j + 3, k + 3), Block.getBlockById(5).getStateFromMeta(0), 3);
		world.setBlockState(new BlockPos(i + 3, j + 3, k + 3), Block.getBlockById(5).getStateFromMeta(0), 3);
		world.setBlockState(new BlockPos(i + 4, j + 3, k + 3), Block.getBlockById(47).getStateFromMeta(0), 3);
		world.setBlockState(new BlockPos(i + 15, j + 3, k + 3), Block.getBlockById(5).getStateFromMeta(0), 3);
		world.setBlockState(new BlockPos(i + 1, j + 3, k + 4), Block.getBlockById(5).getStateFromMeta(0), 3);
		world.setBlockState(new BlockPos(i + 15, j + 3, k + 4), Block.getBlockById(17).getStateFromMeta(1), 3);
		world.setBlockState(new BlockPos(i + 1, j + 3, k + 5), Block.getBlockById(5).getStateFromMeta(0), 3);
		world.setBlockState(new BlockPos(i + 15, j + 3, k + 5), Block.getBlockById(5).getStateFromMeta(0), 3);
		world.setBlockState(new BlockPos(i + 1, j + 3, k + 6), Block.getBlockById(5).getStateFromMeta(0), 3);
		world.setBlockState(new BlockPos(i + 15, j + 3, k + 6), Block.getBlockById(5).getStateFromMeta(0), 3);
		world.setBlockState(new BlockPos(i + 1, j + 3, k + 7), Block.getBlockById(5).getStateFromMeta(0), 3);
		world.setBlockState(new BlockPos(i + 15, j + 3, k + 7), Block.getBlockById(5).getStateFromMeta(0), 3);
		world.setBlockState(new BlockPos(i + 1, j + 3, k + 8), Block.getBlockById(5).getStateFromMeta(0), 3);
		world.setBlockState(new BlockPos(i + 15, j + 3, k + 8), Block.getBlockById(17).getStateFromMeta(1), 3);
		world.setBlockState(new BlockPos(i + 1, j + 3, k + 9), Block.getBlockById(5).getStateFromMeta(0), 3);
		world.setBlockState(new BlockPos(i + 2, j + 3, k + 9), Block.getBlockById(47).getStateFromMeta(0), 3);
		world.setBlockState(new BlockPos(i + 14, j + 3, k + 9), Block.getBlockById(5).getStateFromMeta(0), 3);
		world.setBlockState(new BlockPos(i + 1, j + 3, k + 10), Block.getBlockById(5).getStateFromMeta(0), 3);
		world.setBlockState(new BlockPos(i + 2, j + 3, k + 10), Block.getBlockById(126).getStateFromMeta(9), 3);
		world.setBlockState(new BlockPos(i + 14, j + 3, k + 10), Block.getBlockById(5).getStateFromMeta(0), 3);
		world.setBlockState(new BlockPos(i + 1, j + 3, k + 11), Block.getBlockById(17).getStateFromMeta(9), 3);
		world.setBlockState(new BlockPos(i + 2, j + 3, k + 11), Block.getBlockById(47).getStateFromMeta(0), 3);
		world.setBlockState(new BlockPos(i + 14, j + 3, k + 11), Block.getBlockById(5).getStateFromMeta(0), 3);
		world.setBlockState(new BlockPos(i + 1, j + 3, k + 12), Block.getBlockById(17).getStateFromMeta(9), 3);
		world.setBlockState(new BlockPos(i + 2, j + 3, k + 12), Block.getBlockById(126).getStateFromMeta(9), 3);
		world.setBlockState(new BlockPos(i + 14, j + 3, k + 12), Block.getBlockById(5).getStateFromMeta(0), 3);
		world.setBlockState(new BlockPos(i + 1, j + 3, k + 13), Block.getBlockById(17).getStateFromMeta(9), 3);
		world.setBlockState(new BlockPos(i + 2, j + 3, k + 13), Block.getBlockById(47).getStateFromMeta(0), 3);
		world.setBlockState(new BlockPos(i + 14, j + 3, k + 13), Block.getBlockById(5).getStateFromMeta(0), 3);
		world.setBlockState(new BlockPos(i + 1, j + 3, k + 14), Block.getBlockById(17).getStateFromMeta(9), 3);
		world.setBlockState(new BlockPos(i + 14, j + 3, k + 14), Block.getBlockById(5).getStateFromMeta(0), 3);
		world.setBlockState(new BlockPos(i + 1, j + 3, k + 15), Block.getBlockById(17).getStateFromMeta(9), 3);
		world.setBlockState(new BlockPos(i + 15, j + 3, k + 15), Block.getBlockById(17).getStateFromMeta(1), 3);
		world.setBlockState(new BlockPos(i + 1, j + 3, k + 16), Block.getBlockById(17).getStateFromMeta(9), 3);
		world.setBlockState(new BlockPos(i + 3, j + 3, k + 16), Block.getBlockById(144).getStateFromMeta(1), 3);
		world.setBlockState(new BlockPos(i + 15, j + 3, k + 16), Block.getBlockById(5).getStateFromMeta(0), 3);
		world.setBlockState(new BlockPos(i + 1, j + 3, k + 17), Block.getBlockById(17).getStateFromMeta(1), 3);
		world.setBlockState(new BlockPos(i + 2, j + 3, k + 17), Block.getBlockById(5).getStateFromMeta(0), 3);
		world.setBlockState(new BlockPos(i + 3, j + 3, k + 17), Block.getBlockById(5).getStateFromMeta(0), 3);
		world.setBlockState(new BlockPos(i + 4, j + 3, k + 17), Block.getBlockById(5).getStateFromMeta(0), 3);
		world.setBlockState(new BlockPos(i + 15, j + 3, k + 17), Block.getBlockById(5).getStateFromMeta(0), 3);
		world.setBlockState(new BlockPos(i + 5, j + 3, k + 18), Block.getBlockById(5).getStateFromMeta(0), 3);
		world.setBlockState(new BlockPos(i + 13, j + 3, k + 18), Block.getBlockById(168).getStateFromMeta(0), 3);
		world.setBlockState(new BlockPos(i + 14, j + 3, k + 18), Block.getBlockById(5).getStateFromMeta(0), 3);
		world.setBlockState(new BlockPos(i + 6, j + 3, k + 19), Block.getBlockById(5).getStateFromMeta(0), 3);
		world.setBlockState(new BlockPos(i + 13, j + 3, k + 19), Block.getBlockById(5).getStateFromMeta(0), 3);
		world.setBlockState(new BlockPos(i + 7, j + 3, k + 20), Block.getBlockById(5).getStateFromMeta(0), 3);
		world.setBlockState(new BlockPos(i + 8, j + 3, k + 20), Block.getBlockById(5).getStateFromMeta(0), 3);
		world.setBlockState(new BlockPos(i + 11, j + 3, k + 20), Block.getBlockById(5).getStateFromMeta(0), 3);
		world.setBlockState(new BlockPos(i + 12, j + 3, k + 20), Block.getBlockById(5).getStateFromMeta(0), 3);
		world.setBlockState(new BlockPos(i + 8, j + 3, k + 21), Block.getBlockById(5).getStateFromMeta(0), 3);
		world.setBlockState(new BlockPos(i + 11, j + 3, k + 21), Block.getBlockById(5).getStateFromMeta(0), 3);
		world.setBlockState(new BlockPos(i + 9, j + 3, k + 22), Block.getBlockById(5).getStateFromMeta(0), 3);
		world.setBlockState(new BlockPos(i + 10, j + 3, k + 22), Block.getBlockById(5).getStateFromMeta(0), 3);
		world.setBlockState(new BlockPos(i + 5, j + 4, k + 1), Block.getBlockById(17).getStateFromMeta(5), 3);
		world.setBlockState(new BlockPos(i + 6, j + 4, k + 1), Block.getBlockById(17).getStateFromMeta(5), 3);
		world.setBlockState(new BlockPos(i + 7, j + 4, k + 1), Block.getBlockById(102).getStateFromMeta(0), 3);
		world.setBlockState(new BlockPos(i + 8, j + 4, k + 1), Block.getBlockById(17).getStateFromMeta(5), 3);
		world.setBlockState(new BlockPos(i + 9, j + 4, k + 1), Block.getBlockById(17).getStateFromMeta(5), 3);
		world.setBlockState(new BlockPos(i + 10, j + 4, k + 1), Block.getBlockById(102).getStateFromMeta(0), 3);
		world.setBlockState(new BlockPos(i + 11, j + 4, k + 1), Block.getBlockById(17).getStateFromMeta(5), 3);
		world.setBlockState(new BlockPos(i + 12, j + 4, k + 1), Block.getBlockById(17).getStateFromMeta(5), 3);
		world.setBlockState(new BlockPos(i + 13, j + 4, k + 1), Block.getBlockById(17).getStateFromMeta(5), 3);
		world.setBlockState(new BlockPos(i + 14, j + 4, k + 1), Block.getBlockById(5).getStateFromMeta(0), 3);
		world.setBlockState(new BlockPos(i + 4, j + 4, k + 2), Block.getBlockById(17).getStateFromMeta(5), 3);
		world.setBlockState(new BlockPos(i + 12, j + 4, k + 2), Block.getBlockById(65).getStateFromMeta(3), 3);
		world.setBlockState(new BlockPos(i + 14, j + 4, k + 2), Block.getBlockById(54).getStateFromMeta(3), 3);
		world.setBlockState(new BlockPos(i + 15, j + 4, k + 2), Block.getBlockById(5).getStateFromMeta(0), 3);
		world.setBlockState(new BlockPos(i + 1, j + 4, k + 3), Block.getBlockById(17).getStateFromMeta(1), 3);
		world.setBlockState(new BlockPos(i + 2, j + 4, k + 3), Block.getBlockById(17).getStateFromMeta(5), 3);
		world.setBlockState(new BlockPos(i + 3, j + 4, k + 3), Block.getBlockById(17).getStateFromMeta(5), 3);
		world.setBlockState(new BlockPos(i + 4, j + 4, k + 3), Block.getBlockById(47).getStateFromMeta(0), 3);
		world.setBlockState(new BlockPos(i + 15, j + 4, k + 3), Block.getBlockById(5).getStateFromMeta(0), 3);
		world.setBlockState(new BlockPos(i + 1, j + 4, k + 4), Block.getBlockById(17).getStateFromMeta(9), 3);
		world.setBlockState(new BlockPos(i + 15, j + 4, k + 4), Block.getBlockById(17).getStateFromMeta(1), 3);
		world.setBlockState(new BlockPos(i + 1, j + 4, k + 5), Block.getBlockById(17).getStateFromMeta(9), 3);
		world.setBlockState(new BlockPos(i + 2, j + 4, k + 5), Block.getBlockById(126).getStateFromMeta(9), 3);
		world.setBlockState(new BlockPos(i + 15, j + 4, k + 5), Block.getBlockById(5).getStateFromMeta(0), 3);
		world.setBlockState(new BlockPos(i + 1, j + 4, k + 6), Block.getBlockById(17).getStateFromMeta(9), 3);
		world.setBlockState(new BlockPos(i + 15, j + 4, k + 6), Block.getBlockById(5).getStateFromMeta(0), 3);
		world.setBlockState(new BlockPos(i + 1, j + 4, k + 7), Block.getBlockById(17).getStateFromMeta(9), 3);
		world.setBlockState(new BlockPos(i + 2, j + 4, k + 7), Block.getBlockById(126).getStateFromMeta(9), 3);
		world.setBlockState(new BlockPos(i + 15, j + 4, k + 7), Block.getBlockById(17).getStateFromMeta(9), 3);
		world.setBlockState(new BlockPos(i + 1, j + 4, k + 8), Block.getBlockById(17).getStateFromMeta(9), 3);
		world.setBlockState(new BlockPos(i + 14, j + 4, k + 8), Block.getBlockById(69).getStateFromMeta(10), 3);
		world.setBlockState(new BlockPos(i + 15, j + 4, k + 8), Block.getBlockById(17).getStateFromMeta(9), 3);
		world.setBlockState(new BlockPos(i + 16, j + 4, k + 8), Block.getBlockById(124).getStateFromMeta(0), 3);
		world.setBlockState(new BlockPos(i + 1, j + 4, k + 9), Block.getBlockById(17).getStateFromMeta(9), 3);
		world.setBlockState(new BlockPos(i + 2, j + 4, k + 9), Block.getBlockById(47).getStateFromMeta(0), 3);
		world.setBlockState(new BlockPos(i + 14, j + 4, k + 9), Block.getBlockById(5).getStateFromMeta(0), 3);
		world.setBlockState(new BlockPos(i + 15, j + 4, k + 9), Block.getBlockById(17).getStateFromMeta(9), 3);
		world.setBlockState(new BlockPos(i + 1, j + 4, k + 10), Block.getBlockById(17).getStateFromMeta(9), 3);
		world.setBlockState(new BlockPos(i + 2, j + 4, k + 10), Block.getBlockById(17).getStateFromMeta(5), 3);
		world.setBlockState(new BlockPos(i + 14, j + 4, k + 10), Block.getBlockById(5).getStateFromMeta(0), 3);
		world.setBlockState(new BlockPos(i + 15, j + 4, k + 10), Block.getBlockById(17).getStateFromMeta(9), 3);
		world.setBlockState(new BlockPos(i + 1, j + 4, k + 11), Block.getBlockById(5).getStateFromMeta(0), 3);
		world.setBlockState(new BlockPos(i + 2, j + 4, k + 11), Block.getBlockById(47).getStateFromMeta(0), 3);
		world.setBlockState(new BlockPos(i + 14, j + 4, k + 11), Block.getBlockById(5).getStateFromMeta(0), 3);
		world.setBlockState(new BlockPos(i + 15, j + 4, k + 11), Block.getBlockById(17).getStateFromMeta(9), 3);
		world.setBlockState(new BlockPos(i + 1, j + 4, k + 12), Block.getBlockById(5).getStateFromMeta(0), 3);
		world.setBlockState(new BlockPos(i + 2, j + 4, k + 12), Block.getBlockById(17).getStateFromMeta(5), 3);
		world.setBlockState(new BlockPos(i + 14, j + 4, k + 12), Block.getBlockById(5).getStateFromMeta(0), 3);
		world.setBlockState(new BlockPos(i + 15, j + 4, k + 12), Block.getBlockById(17).getStateFromMeta(9), 3);
		world.setBlockState(new BlockPos(i + 1, j + 4, k + 13), Block.getBlockById(5).getStateFromMeta(0), 3);
		world.setBlockState(new BlockPos(i + 2, j + 4, k + 13), Block.getBlockById(47).getStateFromMeta(0), 3);
		world.setBlockState(new BlockPos(i + 14, j + 4, k + 13), Block.getBlockById(5).getStateFromMeta(0), 3);
		world.setBlockState(new BlockPos(i + 15, j + 4, k + 13), Block.getBlockById(17).getStateFromMeta(9), 3);
		world.setBlockState(new BlockPos(i + 1, j + 4, k + 14), Block.getBlockById(5).getStateFromMeta(0), 3);
		world.setBlockState(new BlockPos(i + 14, j + 4, k + 14), Block.getBlockById(5).getStateFromMeta(0), 3);
		world.setBlockState(new BlockPos(i + 15, j + 4, k + 14), Block.getBlockById(17).getStateFromMeta(9), 3);
		world.setBlockState(new BlockPos(i + 1, j + 4, k + 15), Block.getBlockById(5).getStateFromMeta(0), 3);
		world.setBlockState(new BlockPos(i + 14, j + 4, k + 15), Block.getBlockById(69).getStateFromMeta(10), 3);
		world.setBlockState(new BlockPos(i + 15, j + 4, k + 15), Block.getBlockById(17).getStateFromMeta(9), 3);
		world.setBlockState(new BlockPos(i + 16, j + 4, k + 15), Block.getBlockById(124).getStateFromMeta(0), 3);
		world.setBlockState(new BlockPos(i + 1, j + 4, k + 16), Block.getBlockById(5).getStateFromMeta(0), 3);
		world.setBlockState(new BlockPos(i + 15, j + 4, k + 16), Block.getBlockById(17).getStateFromMeta(9), 3);
		world.setBlockState(new BlockPos(i + 1, j + 4, k + 17), Block.getBlockById(17).getStateFromMeta(1), 3);
		world.setBlockState(new BlockPos(i + 2, j + 4, k + 17), Block.getBlockById(102).getStateFromMeta(0), 3);
		world.setBlockState(new BlockPos(i + 3, j + 4, k + 17), Block.getBlockById(102).getStateFromMeta(0), 3);
		world.setBlockState(new BlockPos(i + 4, j + 4, k + 17), Block.getBlockById(5).getStateFromMeta(0), 3);
		world.setBlockState(new BlockPos(i + 15, j + 4, k + 17), Block.getBlockById(5).getStateFromMeta(0), 3);
		world.setBlockState(new BlockPos(i + 16, j + 4, k + 17), Block.getBlockById(177).getStateFromMeta(5), 3);
		world.setBlockState(new BlockPos(i + 4, j + 4, k + 18), Block.getBlockById(5).getStateFromMeta(0), 3);
		world.setBlockState(new BlockPos(i + 15, j + 4, k + 18), Block.getBlockById(17).getStateFromMeta(9), 3);
		world.setBlockState(new BlockPos(i + 5, j + 4, k + 19), Block.getBlockById(5).getStateFromMeta(0), 3);
		world.setBlockState(new BlockPos(i + 13, j + 4, k + 19), Block.getBlockById(30).getStateFromMeta(0), 3);
		world.setBlockState(new BlockPos(i + 14, j + 4, k + 19), Block.getBlockById(5).getStateFromMeta(0), 3);
		world.setBlockState(new BlockPos(i + 6, j + 4, k + 20), Block.getBlockById(5).getStateFromMeta(0), 3);
		world.setBlockState(new BlockPos(i + 13, j + 4, k + 20), Block.getBlockById(5).getStateFromMeta(0), 3);
		world.setBlockState(new BlockPos(i + 7, j + 4, k + 21), Block.getBlockById(5).getStateFromMeta(0), 3);
		world.setBlockState(new BlockPos(i + 12, j + 4, k + 21), Block.getBlockById(5).getStateFromMeta(0), 3);
		world.setBlockState(new BlockPos(i + 8, j + 4, k + 22), Block.getBlockById(5).getStateFromMeta(0), 3);
		world.setBlockState(new BlockPos(i + 11, j + 4, k + 22), Block.getBlockById(5).getStateFromMeta(0), 3);
		world.setBlockState(new BlockPos(i + 9, j + 4, k + 23), Block.getBlockById(5).getStateFromMeta(0), 3);
		world.setBlockState(new BlockPos(i + 10, j + 4, k + 23), Block.getBlockById(5).getStateFromMeta(0), 3);
		world.setBlockState(new BlockPos(i + 5, j + 5, k + 1), Block.getBlockById(5).getStateFromMeta(0), 3);
		world.setBlockState(new BlockPos(i + 6, j + 5, k + 1), Block.getBlockById(5).getStateFromMeta(0), 3);
		world.setBlockState(new BlockPos(i + 7, j + 5, k + 1), Block.getBlockById(17).getStateFromMeta(1), 3);
		world.setBlockState(new BlockPos(i + 8, j + 5, k + 1), Block.getBlockById(5).getStateFromMeta(0), 3);
		world.setBlockState(new BlockPos(i + 9, j + 5, k + 1), Block.getBlockById(5).getStateFromMeta(0), 3);
		world.setBlockState(new BlockPos(i + 10, j + 5, k + 1), Block.getBlockById(17).getStateFromMeta(1), 3);
		world.setBlockState(new BlockPos(i + 11, j + 5, k + 1), Block.getBlockById(5).getStateFromMeta(0), 3);
		world.setBlockState(new BlockPos(i + 12, j + 5, k + 1), Block.getBlockById(5).getStateFromMeta(0), 3);
		world.setBlockState(new BlockPos(i + 13, j + 5, k + 1), Block.getBlockById(5).getStateFromMeta(0), 3);
		world.setBlockState(new BlockPos(i + 14, j + 5, k + 1), Block.getBlockById(5).getStateFromMeta(0), 3);
		world.setBlockState(new BlockPos(i + 4, j + 5, k + 2), Block.getBlockById(5).getStateFromMeta(0), 3);
		world.setBlockState(new BlockPos(i + 12, j + 5, k + 2), Block.getBlockById(65).getStateFromMeta(3), 3);
		world.setBlockState(new BlockPos(i + 15, j + 5, k + 2), Block.getBlockById(5).getStateFromMeta(0), 3);
		world.setBlockState(new BlockPos(i + 1, j + 5, k + 3), Block.getBlockById(17).getStateFromMeta(1), 3);
		world.setBlockState(new BlockPos(i + 2, j + 5, k + 3), Block.getBlockById(5).getStateFromMeta(0), 3);
		world.setBlockState(new BlockPos(i + 3, j + 5, k + 3), Block.getBlockById(5).getStateFromMeta(0), 3);
		world.setBlockState(new BlockPos(i + 4, j + 5, k + 3), Block.getBlockById(47).getStateFromMeta(0), 3);
		world.setBlockState(new BlockPos(i + 15, j + 5, k + 3), Block.getBlockById(102).getStateFromMeta(0), 3);
		world.setBlockState(new BlockPos(i + 1, j + 5, k + 4), Block.getBlockById(5).getStateFromMeta(0), 3);
		world.setBlockState(new BlockPos(i + 2, j + 5, k + 4), Block.getBlockById(17).getStateFromMeta(5), 3);
		world.setBlockState(new BlockPos(i + 15, j + 5, k + 4), Block.getBlockById(17).getStateFromMeta(1), 3);
		world.setBlockState(new BlockPos(i + 1, j + 5, k + 5), Block.getBlockById(5).getStateFromMeta(0), 3);
		world.setBlockState(new BlockPos(i + 2, j + 5, k + 5), Block.getBlockById(188).getStateFromMeta(0), 3);
		world.setBlockState(new BlockPos(i + 15, j + 5, k + 5), Block.getBlockById(102).getStateFromMeta(0), 3);
		world.setBlockState(new BlockPos(i + 1, j + 5, k + 6), Block.getBlockById(5).getStateFromMeta(0), 3);
		world.setBlockState(new BlockPos(i + 2, j + 5, k + 6), Block.getBlockById(17).getStateFromMeta(5), 3);
		world.setBlockState(new BlockPos(i + 13, j + 5, k + 6), Block.getBlockById(17).getStateFromMeta(1), 3);
		world.setBlockState(new BlockPos(i + 14, j + 5, k + 6), Block.getBlockById(5).getStateFromMeta(0), 3);
		world.setBlockState(new BlockPos(i + 15, j + 5, k + 6), Block.getBlockById(17).getStateFromMeta(9), 3);
		world.setBlockState(new BlockPos(i + 16, j + 5, k + 6), Block.getBlockById(177).getStateFromMeta(5), 3);
		world.setBlockState(new BlockPos(i + 1, j + 5, k + 7), Block.getBlockById(5).getStateFromMeta(0), 3);
		world.setBlockState(new BlockPos(i + 2, j + 5, k + 7), Block.getBlockById(188).getStateFromMeta(0), 3);
		world.setBlockState(new BlockPos(i + 13, j + 5, k + 7), Block.getBlockById(5).getStateFromMeta(0), 3);
		world.setBlockState(new BlockPos(i + 14, j + 5, k + 7), Block.getBlockById(5).getStateFromMeta(0), 3);
		world.setBlockState(new BlockPos(i + 15, j + 5, k + 7), Block.getBlockById(188).getStateFromMeta(0), 3);
		world.setBlockState(new BlockPos(i + 1, j + 5, k + 8), Block.getBlockById(5).getStateFromMeta(0), 3);
		world.setBlockState(new BlockPos(i + 2, j + 5, k + 8), Block.getBlockById(17).getStateFromMeta(5), 3);
		world.setBlockState(new BlockPos(i + 13, j + 5, k + 8), Block.getBlockById(5).getStateFromMeta(0), 3);
		world.setBlockState(new BlockPos(i + 14, j + 5, k + 8), Block.getBlockById(5).getStateFromMeta(0), 3);
		world.setBlockState(new BlockPos(i + 15, j + 5, k + 8), Block.getBlockById(188).getStateFromMeta(0), 3);
		world.setBlockState(new BlockPos(i + 16, j + 5, k + 8), Block.getBlockById(188).getStateFromMeta(0), 3);
		world.setBlockState(new BlockPos(i + 1, j + 5, k + 9), Block.getBlockById(5).getStateFromMeta(0), 3);
		world.setBlockState(new BlockPos(i + 2, j + 5, k + 9), Block.getBlockById(66).getStateFromMeta(0), 3);
		world.setBlockState(new BlockPos(i + 13, j + 5, k + 9), Block.getBlockById(17).getStateFromMeta(1), 3);
		world.setBlockState(new BlockPos(i + 15, j + 5, k + 9), Block.getBlockById(188).getStateFromMeta(0), 3);
		world.setBlockState(new BlockPos(i + 1, j + 5, k + 10), Block.getBlockById(5).getStateFromMeta(0), 3);
		world.setBlockState(new BlockPos(i + 2, j + 5, k + 10), Block.getBlockById(124).getStateFromMeta(0), 3);
		world.setBlockState(new BlockPos(i + 13, j + 5, k + 10), Block.getBlockById(5).getStateFromMeta(0), 3);
		world.setBlockState(new BlockPos(i + 15, j + 5, k + 10), Block.getBlockById(188).getStateFromMeta(0), 3);
		world.setBlockState(new BlockPos(i + 1, j + 5, k + 11), Block.getBlockById(17).getStateFromMeta(9), 3);
		world.setBlockState(new BlockPos(i + 2, j + 5, k + 11), Block.getBlockById(69).getStateFromMeta(9), 3);
		world.setBlockState(new BlockPos(i + 13, j + 5, k + 11), Block.getBlockById(5).getStateFromMeta(0), 3);
		world.setBlockState(new BlockPos(i + 15, j + 5, k + 11), Block.getBlockById(188).getStateFromMeta(0), 3);
		world.setBlockState(new BlockPos(i + 1, j + 5, k + 12), Block.getBlockById(17).getStateFromMeta(9), 3);
		world.setBlockState(new BlockPos(i + 2, j + 5, k + 12), Block.getBlockById(124).getStateFromMeta(0), 3);
		world.setBlockState(new BlockPos(i + 13, j + 5, k + 12), Block.getBlockById(5).getStateFromMeta(0), 3);
		world.setBlockState(new BlockPos(i + 15, j + 5, k + 12), Block.getBlockById(188).getStateFromMeta(0), 3);
		world.setBlockState(new BlockPos(i + 1, j + 5, k + 13), Block.getBlockById(17).getStateFromMeta(9), 3);
		world.setBlockState(new BlockPos(i + 2, j + 5, k + 13), Block.getBlockById(140).getStateFromMeta(0), 3);
		world.setBlockState(new BlockPos(i + 13, j + 5, k + 13), Block.getBlockById(17).getStateFromMeta(1), 3);
		world.setBlockState(new BlockPos(i + 15, j + 5, k + 13), Block.getBlockById(188).getStateFromMeta(0), 3);
		world.setBlockState(new BlockPos(i + 1, j + 5, k + 14), Block.getBlockById(17).getStateFromMeta(9), 3);
		world.setBlockState(new BlockPos(i + 13, j + 5, k + 14), Block.getBlockById(5).getStateFromMeta(0), 3);
		world.setBlockState(new BlockPos(i + 15, j + 5, k + 14), Block.getBlockById(188).getStateFromMeta(0), 3);
		world.setBlockState(new BlockPos(i + 1, j + 5, k + 15), Block.getBlockById(17).getStateFromMeta(9), 3);
		world.setBlockState(new BlockPos(i + 13, j + 5, k + 15), Block.getBlockById(5).getStateFromMeta(0), 3);
		world.setBlockState(new BlockPos(i + 14, j + 5, k + 15), Block.getBlockById(5).getStateFromMeta(0), 3);
		world.setBlockState(new BlockPos(i + 15, j + 5, k + 15), Block.getBlockById(188).getStateFromMeta(0), 3);
		world.setBlockState(new BlockPos(i + 16, j + 5, k + 15), Block.getBlockById(188).getStateFromMeta(0), 3);
		world.setBlockState(new BlockPos(i + 1, j + 5, k + 16), Block.getBlockById(17).getStateFromMeta(9), 3);
		world.setBlockState(new BlockPos(i + 14, j + 5, k + 16), Block.getBlockById(5).getStateFromMeta(0), 3);
		world.setBlockState(new BlockPos(i + 15, j + 5, k + 16), Block.getBlockById(17).getStateFromMeta(9), 3);
		world.setBlockState(new BlockPos(i + 1, j + 5, k + 17), Block.getBlockById(5).getStateFromMeta(0), 3);
		world.setBlockState(new BlockPos(i + 2, j + 5, k + 17), Block.getBlockById(5).getStateFromMeta(0), 3);
		world.setBlockState(new BlockPos(i + 3, j + 5, k + 17), Block.getBlockById(5).getStateFromMeta(0), 3);
		world.setBlockState(new BlockPos(i + 4, j + 5, k + 17), Block.getBlockById(124).getStateFromMeta(0), 3);
		world.setBlockState(new BlockPos(i + 5, j + 5, k + 17), Block.getBlockById(69).getStateFromMeta(9), 3);
		world.setBlockState(new BlockPos(i + 14, j + 5, k + 17), Block.getBlockById(5).getStateFromMeta(0), 3);
		world.setBlockState(new BlockPos(i + 15, j + 5, k + 17), Block.getBlockById(17).getStateFromMeta(9), 3);
		world.setBlockState(new BlockPos(i + 4, j + 5, k + 18), Block.getBlockById(17).getStateFromMeta(5), 3);
		world.setBlockState(new BlockPos(i + 5, j + 5, k + 18), Block.getBlockById(5).getStateFromMeta(0), 3);
		world.setBlockState(new BlockPos(i + 6, j + 5, k + 18), Block.getBlockById(5).getStateFromMeta(0), 3);
		world.setBlockState(new BlockPos(i + 7, j + 5, k + 18), Block.getBlockById(5).getStateFromMeta(0), 3);
		world.setBlockState(new BlockPos(i + 8, j + 5, k + 18), Block.getBlockById(5).getStateFromMeta(0), 3);
		world.setBlockState(new BlockPos(i + 9, j + 5, k + 18), Block.getBlockById(5).getStateFromMeta(0), 3);
		world.setBlockState(new BlockPos(i + 10, j + 5, k + 18), Block.getBlockById(5).getStateFromMeta(0), 3);
		world.setBlockState(new BlockPos(i + 11, j + 5, k + 18), Block.getBlockById(5).getStateFromMeta(0), 3);
		world.setBlockState(new BlockPos(i + 12, j + 5, k + 18), Block.getBlockById(5).getStateFromMeta(0), 3);
		world.setBlockState(new BlockPos(i + 13, j + 5, k + 18), Block.getBlockById(5).getStateFromMeta(0), 3);
		world.setBlockState(new BlockPos(i + 14, j + 5, k + 18), Block.getBlockById(5).getStateFromMeta(0), 3);
		world.setBlockState(new BlockPos(i + 15, j + 5, k + 18), Block.getBlockById(17).getStateFromMeta(9), 3);
		world.setBlockState(new BlockPos(i + 4, j + 5, k + 19), Block.getBlockById(17).getStateFromMeta(9), 3);
		world.setBlockState(new BlockPos(i + 5, j + 5, k + 19), Block.getBlockById(17).getStateFromMeta(5), 3);
		world.setBlockState(new BlockPos(i + 6, j + 5, k + 19), Block.getBlockById(5).getStateFromMeta(0), 3);
		world.setBlockState(new BlockPos(i + 7, j + 5, k + 19), Block.getBlockById(5).getStateFromMeta(0), 3);
		world.setBlockState(new BlockPos(i + 8, j + 5, k + 19), Block.getBlockById(5).getStateFromMeta(0), 3);
		world.setBlockState(new BlockPos(i + 9, j + 5, k + 19), Block.getBlockById(5).getStateFromMeta(0), 3);
		world.setBlockState(new BlockPos(i + 10, j + 5, k + 19), Block.getBlockById(5).getStateFromMeta(0), 3);
		world.setBlockState(new BlockPos(i + 11, j + 5, k + 19), Block.getBlockById(5).getStateFromMeta(0), 3);
		world.setBlockState(new BlockPos(i + 12, j + 5, k + 19), Block.getBlockById(5).getStateFromMeta(0), 3);
		world.setBlockState(new BlockPos(i + 13, j + 5, k + 19), Block.getBlockById(5).getStateFromMeta(0), 3);
		world.setBlockState(new BlockPos(i + 14, j + 5, k + 19), Block.getBlockById(17).getStateFromMeta(5), 3);
		world.setBlockState(new BlockPos(i + 15, j + 5, k + 19), Block.getBlockById(17).getStateFromMeta(9), 3);
		world.setBlockState(new BlockPos(i + 5, j + 5, k + 20), Block.getBlockById(17).getStateFromMeta(9), 3);
		world.setBlockState(new BlockPos(i + 6, j + 5, k + 20), Block.getBlockById(17).getStateFromMeta(5), 3);
		world.setBlockState(new BlockPos(i + 7, j + 5, k + 20), Block.getBlockById(5).getStateFromMeta(0), 3);
		world.setBlockState(new BlockPos(i + 8, j + 5, k + 20), Block.getBlockById(5).getStateFromMeta(0), 3);
		world.setBlockState(new BlockPos(i + 9, j + 5, k + 20), Block.getBlockById(5).getStateFromMeta(0), 3);
		world.setBlockState(new BlockPos(i + 10, j + 5, k + 20), Block.getBlockById(5).getStateFromMeta(0), 3);
		world.setBlockState(new BlockPos(i + 11, j + 5, k + 20), Block.getBlockById(5).getStateFromMeta(0), 3);
		world.setBlockState(new BlockPos(i + 12, j + 5, k + 20), Block.getBlockById(5).getStateFromMeta(0), 3);
		world.setBlockState(new BlockPos(i + 13, j + 5, k + 20), Block.getBlockById(17).getStateFromMeta(5), 3);
		world.setBlockState(new BlockPos(i + 14, j + 5, k + 20), Block.getBlockById(17).getStateFromMeta(9), 3);
		world.setBlockState(new BlockPos(i + 6, j + 5, k + 21), Block.getBlockById(17).getStateFromMeta(9), 3);
		world.setBlockState(new BlockPos(i + 7, j + 5, k + 21), Block.getBlockById(17).getStateFromMeta(5), 3);
		world.setBlockState(new BlockPos(i + 8, j + 5, k + 21), Block.getBlockById(5).getStateFromMeta(0), 3);
		world.setBlockState(new BlockPos(i + 9, j + 5, k + 21), Block.getBlockById(5).getStateFromMeta(0), 3);
		world.setBlockState(new BlockPos(i + 10, j + 5, k + 21), Block.getBlockById(5).getStateFromMeta(0), 3);
		world.setBlockState(new BlockPos(i + 11, j + 5, k + 21), Block.getBlockById(5).getStateFromMeta(0), 3);
		world.setBlockState(new BlockPos(i + 12, j + 5, k + 21), Block.getBlockById(17).getStateFromMeta(5), 3);
		world.setBlockState(new BlockPos(i + 13, j + 5, k + 21), Block.getBlockById(17).getStateFromMeta(9), 3);
		world.setBlockState(new BlockPos(i + 7, j + 5, k + 22), Block.getBlockById(17).getStateFromMeta(9), 3);
		world.setBlockState(new BlockPos(i + 8, j + 5, k + 22), Block.getBlockById(17).getStateFromMeta(5), 3);
		world.setBlockState(new BlockPos(i + 9, j + 5, k + 22), Block.getBlockById(5).getStateFromMeta(0), 3);
		world.setBlockState(new BlockPos(i + 10, j + 5, k + 22), Block.getBlockById(5).getStateFromMeta(0), 3);
		world.setBlockState(new BlockPos(i + 11, j + 5, k + 22), Block.getBlockById(17).getStateFromMeta(5), 3);
		world.setBlockState(new BlockPos(i + 12, j + 5, k + 22), Block.getBlockById(17).getStateFromMeta(9), 3);
		world.setBlockState(new BlockPos(i + 8, j + 5, k + 23), Block.getBlockById(17).getStateFromMeta(9), 3);
		world.setBlockState(new BlockPos(i + 9, j + 5, k + 23), Block.getBlockById(5).getStateFromMeta(0), 3);
		world.setBlockState(new BlockPos(i + 10, j + 5, k + 23), Block.getBlockById(5).getStateFromMeta(0), 3);
		world.setBlockState(new BlockPos(i + 11, j + 5, k + 23), Block.getBlockById(17).getStateFromMeta(9), 3);
		world.setBlockState(new BlockPos(i + 9, j + 5, k + 24), Block.getBlockById(5).getStateFromMeta(0), 3);
		world.setBlockState(new BlockPos(i + 10, j + 5, k + 24), Block.getBlockById(5).getStateFromMeta(0), 3);
		world.setBlockState(new BlockPos(i + 9, j + 5, k + 25), Block.getBlockById(5).getStateFromMeta(0), 3);
		world.setBlockState(new BlockPos(i + 10, j + 5, k + 25), Block.getBlockById(5).getStateFromMeta(0), 3);
		world.setBlockState(new BlockPos(i + 5, j + 6, k + 1), Block.getBlockById(17).getStateFromMeta(5), 3);
		world.setBlockState(new BlockPos(i + 6, j + 6, k + 1), Block.getBlockById(17).getStateFromMeta(5), 3);
		world.setBlockState(new BlockPos(i + 7, j + 6, k + 1), Block.getBlockById(17).getStateFromMeta(5), 3);
		world.setBlockState(new BlockPos(i + 8, j + 6, k + 1), Block.getBlockById(17).getStateFromMeta(5), 3);
		world.setBlockState(new BlockPos(i + 9, j + 6, k + 1), Block.getBlockById(17).getStateFromMeta(5), 3);
		world.setBlockState(new BlockPos(i + 10, j + 6, k + 1), Block.getBlockById(17).getStateFromMeta(5), 3);
		world.setBlockState(new BlockPos(i + 11, j + 6, k + 1), Block.getBlockById(17).getStateFromMeta(5), 3);
		world.setBlockState(new BlockPos(i + 12, j + 6, k + 1), Block.getBlockById(17).getStateFromMeta(5), 3);
		world.setBlockState(new BlockPos(i + 13, j + 6, k + 1), Block.getBlockById(17).getStateFromMeta(5), 3);
		world.setBlockState(new BlockPos(i + 14, j + 6, k + 1), Block.getBlockById(5).getStateFromMeta(0), 3);
		world.setBlockState(new BlockPos(i + 4, j + 6, k + 2), Block.getBlockById(17).getStateFromMeta(5), 3);
		world.setBlockState(new BlockPos(i + 5, j + 6, k + 2), Block.getBlockById(30).getStateFromMeta(0), 3);
		world.setBlockState(new BlockPos(i + 12, j + 6, k + 2), Block.getBlockById(65).getStateFromMeta(3), 3);
		world.setBlockState(new BlockPos(i + 13, j + 6, k + 2), Block.getBlockById(69).getStateFromMeta(10), 3);
		world.setBlockState(new BlockPos(i + 14, j + 6, k + 2), Block.getBlockById(124).getStateFromMeta(0), 3);
		world.setBlockState(new BlockPos(i + 15, j + 6, k + 2), Block.getBlockById(17).getStateFromMeta(9), 3);
		world.setBlockState(new BlockPos(i + 1, j + 6, k + 3), Block.getBlockById(17).getStateFromMeta(1), 3);
		world.setBlockState(new BlockPos(i + 2, j + 6, k + 3), Block.getBlockById(17).getStateFromMeta(5), 3);
		world.setBlockState(new BlockPos(i + 3, j + 6, k + 3), Block.getBlockById(17).getStateFromMeta(5), 3);
		world.setBlockState(new BlockPos(i + 4, j + 6, k + 3), Block.getBlockById(47).getStateFromMeta(0), 3);
		world.setBlockState(new BlockPos(i + 14, j + 6, k + 3), Block.getBlockById(5).getStateFromMeta(0), 3);
		world.setBlockState(new BlockPos(i + 15, j + 6, k + 3), Block.getBlockById(17).getStateFromMeta(9), 3);
		world.setBlockState(new BlockPos(i + 1, j + 6, k + 4), Block.getBlockById(17).getStateFromMeta(9), 3);
		world.setBlockState(new BlockPos(i + 2, j + 6, k + 4), Block.getBlockById(54).getStateFromMeta(5), 3);
		world.setBlockState(new BlockPos(i + 14, j + 6, k + 4), Block.getBlockById(5).getStateFromMeta(0), 3);
		world.setBlockState(new BlockPos(i + 15, j + 6, k + 4), Block.getBlockById(17).getStateFromMeta(9), 3);
		world.setBlockState(new BlockPos(i + 1, j + 6, k + 5), Block.getBlockById(17).getStateFromMeta(9), 3);
		world.setBlockState(new BlockPos(i + 2, j + 6, k + 5), Block.getBlockById(17).getStateFromMeta(5), 3);
		world.setBlockState(new BlockPos(i + 14, j + 6, k + 5), Block.getBlockById(5).getStateFromMeta(0), 3);
		world.setBlockState(new BlockPos(i + 15, j + 6, k + 5), Block.getBlockById(17).getStateFromMeta(9), 3);
		world.setBlockState(new BlockPos(i + 1, j + 6, k + 6), Block.getBlockById(17).getStateFromMeta(9), 3);
		world.setBlockState(new BlockPos(i + 2, j + 6, k + 6), Block.getBlockById(54).getStateFromMeta(5), 3);
		world.setBlockState(new BlockPos(i + 13, j + 6, k + 6), Block.getBlockById(17).getStateFromMeta(1), 3);
		world.setBlockState(new BlockPos(i + 15, j + 6, k + 6), Block.getBlockById(188).getStateFromMeta(0), 3);
		world.setBlockState(new BlockPos(i + 1, j + 6, k + 7), Block.getBlockById(17).getStateFromMeta(9), 3);
		world.setBlockState(new BlockPos(i + 2, j + 6, k + 7), Block.getBlockById(17).getStateFromMeta(5), 3);
		world.setBlockState(new BlockPos(i + 13, j + 6, k + 7), Block.getBlockById(5).getStateFromMeta(0), 3);
		world.setBlockState(new BlockPos(i + 1, j + 6, k + 8), Block.getBlockById(17).getStateFromMeta(9), 3);
		world.setBlockState(new BlockPos(i + 2, j + 6, k + 8), Block.getBlockById(54).getStateFromMeta(5), 3);
		world.setBlockState(new BlockPos(i + 13, j + 6, k + 8), Block.getBlockById(5).getStateFromMeta(0), 3);
		world.setBlockState(new BlockPos(i + 1, j + 6, k + 9), Block.getBlockById(17).getStateFromMeta(9), 3);
		world.setBlockState(new BlockPos(i + 2, j + 6, k + 9), Block.getBlockById(126).getStateFromMeta(1), 3);
		world.setBlockState(new BlockPos(i + 13, j + 6, k + 9), Block.getBlockById(17).getStateFromMeta(1), 3);
		world.setBlockState(new BlockPos(i + 1, j + 6, k + 10), Block.getBlockById(17).getStateFromMeta(9), 3);
		world.setBlockState(new BlockPos(i + 2, j + 6, k + 10), Block.getBlockById(17).getStateFromMeta(5), 3);
		world.setBlockState(new BlockPos(i + 3, j + 6, k + 10), Block.getBlockById(17).getStateFromMeta(5), 3);
		world.setBlockState(new BlockPos(i + 4, j + 6, k + 10), Block.getBlockById(17).getStateFromMeta(5), 3);
		world.setBlockState(new BlockPos(i + 5, j + 6, k + 10), Block.getBlockById(17).getStateFromMeta(5), 3);
		world.setBlockState(new BlockPos(i + 6, j + 6, k + 10), Block.getBlockById(17).getStateFromMeta(5), 3);
		world.setBlockState(new BlockPos(i + 7, j + 6, k + 10), Block.getBlockById(17).getStateFromMeta(5), 3);
		world.setBlockState(new BlockPos(i + 8, j + 6, k + 10), Block.getBlockById(17).getStateFromMeta(5), 3);
		world.setBlockState(new BlockPos(i + 9, j + 6, k + 10), Block.getBlockById(17).getStateFromMeta(5), 3);
		world.setBlockState(new BlockPos(i + 10, j + 6, k + 10), Block.getBlockById(17).getStateFromMeta(5), 3);
		world.setBlockState(new BlockPos(i + 11, j + 6, k + 10), Block.getBlockById(17).getStateFromMeta(5), 3);
		world.setBlockState(new BlockPos(i + 12, j + 6, k + 10), Block.getBlockById(17).getStateFromMeta(5), 3);
		world.setBlockState(new BlockPos(i + 13, j + 6, k + 10), Block.getBlockById(17).getStateFromMeta(9), 3);
		world.setBlockState(new BlockPos(i + 0, j + 6, k + 11), Block.getBlockById(17).getStateFromMeta(5), 3);
		world.setBlockState(new BlockPos(i + 1, j + 6, k + 11), Block.getBlockById(5).getStateFromMeta(0), 3);
		world.setBlockState(new BlockPos(i + 2, j + 6, k + 11), Block.getBlockById(5).getStateFromMeta(0), 3);
		world.setBlockState(new BlockPos(i + 3, j + 6, k + 11), Block.getBlockById(5).getStateFromMeta(0), 3);
		world.setBlockState(new BlockPos(i + 4, j + 6, k + 11), Block.getBlockById(5).getStateFromMeta(0), 3);
		world.setBlockState(new BlockPos(i + 5, j + 6, k + 11), Block.getBlockById(5).getStateFromMeta(0), 3);
		world.setBlockState(new BlockPos(i + 6, j + 6, k + 11), Block.getBlockById(5).getStateFromMeta(0), 3);
		world.setBlockState(new BlockPos(i + 7, j + 6, k + 11), Block.getBlockById(5).getStateFromMeta(0), 3);
		world.setBlockState(new BlockPos(i + 8, j + 6, k + 11), Block.getBlockById(5).getStateFromMeta(0), 3);
		world.setBlockState(new BlockPos(i + 9, j + 6, k + 11), Block.getBlockById(5).getStateFromMeta(0), 3);
		world.setBlockState(new BlockPos(i + 10, j + 6, k + 11), Block.getBlockById(5).getStateFromMeta(0), 3);
		world.setBlockState(new BlockPos(i + 11, j + 6, k + 11), Block.getBlockById(5).getStateFromMeta(0), 3);
		world.setBlockState(new BlockPos(i + 12, j + 6, k + 11), Block.getBlockById(5).getStateFromMeta(0), 3);
		world.setBlockState(new BlockPos(i + 13, j + 6, k + 11), Block.getBlockById(17).getStateFromMeta(9), 3);
		world.setBlockState(new BlockPos(i + 0, j + 6, k + 12), Block.getBlockById(17).getStateFromMeta(5), 3);
		world.setBlockState(new BlockPos(i + 1, j + 6, k + 12), Block.getBlockById(5).getStateFromMeta(0), 3);
		world.setBlockState(new BlockPos(i + 2, j + 6, k + 12), Block.getBlockById(5).getStateFromMeta(0), 3);
		world.setBlockState(new BlockPos(i + 3, j + 6, k + 12), Block.getBlockById(5).getStateFromMeta(0), 3);
		world.setBlockState(new BlockPos(i + 4, j + 6, k + 12), Block.getBlockById(5).getStateFromMeta(0), 3);
		world.setBlockState(new BlockPos(i + 5, j + 6, k + 12), Block.getBlockById(17).getStateFromMeta(9), 3);
		world.setBlockState(new BlockPos(i + 6, j + 6, k + 12), Block.getBlockById(5).getStateFromMeta(0), 3);
		world.setBlockState(new BlockPos(i + 7, j + 6, k + 12), Block.getBlockById(5).getStateFromMeta(0), 3);
		world.setBlockState(new BlockPos(i + 8, j + 6, k + 12), Block.getBlockById(17).getStateFromMeta(9), 3);
		world.setBlockState(new BlockPos(i + 9, j + 6, k + 12), Block.getBlockById(5).getStateFromMeta(0), 3);
		world.setBlockState(new BlockPos(i + 10, j + 6, k + 12), Block.getBlockById(5).getStateFromMeta(0), 3);
		world.setBlockState(new BlockPos(i + 11, j + 6, k + 12), Block.getBlockById(5).getStateFromMeta(0), 3);
		world.setBlockState(new BlockPos(i + 12, j + 6, k + 12), Block.getBlockById(5).getStateFromMeta(0), 3);
		world.setBlockState(new BlockPos(i + 13, j + 6, k + 12), Block.getBlockById(17).getStateFromMeta(9), 3);
		world.setBlockState(new BlockPos(i + 0, j + 6, k + 13), Block.getBlockById(17).getStateFromMeta(5), 3);
		world.setBlockState(new BlockPos(i + 1, j + 6, k + 13), Block.getBlockById(5).getStateFromMeta(0), 3);
		world.setBlockState(new BlockPos(i + 2, j + 6, k + 13), Block.getBlockById(5).getStateFromMeta(0), 3);
		world.setBlockState(new BlockPos(i + 3, j + 6, k + 13), Block.getBlockById(5).getStateFromMeta(0), 3);
		world.setBlockState(new BlockPos(i + 4, j + 6, k + 13), Block.getBlockById(5).getStateFromMeta(0), 3);
		world.setBlockState(new BlockPos(i + 5, j + 6, k + 13), Block.getBlockById(5).getStateFromMeta(0), 3);
		world.setBlockState(new BlockPos(i + 8, j + 6, k + 13), Block.getBlockById(5).getStateFromMeta(0), 3);
		world.setBlockState(new BlockPos(i + 9, j + 6, k + 13), Block.getBlockById(5).getStateFromMeta(0), 3);
		world.setBlockState(new BlockPos(i + 10, j + 6, k + 13), Block.getBlockById(5).getStateFromMeta(0), 3);
		world.setBlockState(new BlockPos(i + 11, j + 6, k + 13), Block.getBlockById(5).getStateFromMeta(0), 3);
		world.setBlockState(new BlockPos(i + 12, j + 6, k + 13), Block.getBlockById(5).getStateFromMeta(0), 3);
		world.setBlockState(new BlockPos(i + 13, j + 6, k + 13), Block.getBlockById(17).getStateFromMeta(9), 3);
		world.setBlockState(new BlockPos(i + 0, j + 6, k + 14), Block.getBlockById(17).getStateFromMeta(5), 3);
		world.setBlockState(new BlockPos(i + 1, j + 6, k + 14), Block.getBlockById(5).getStateFromMeta(0), 3);
		world.setBlockState(new BlockPos(i + 2, j + 6, k + 14), Block.getBlockById(5).getStateFromMeta(0), 3);
		world.setBlockState(new BlockPos(i + 3, j + 6, k + 14), Block.getBlockById(5).getStateFromMeta(0), 3);
		world.setBlockState(new BlockPos(i + 4, j + 6, k + 14), Block.getBlockById(5).getStateFromMeta(0), 3);
		world.setBlockState(new BlockPos(i + 5, j + 6, k + 14), Block.getBlockById(5).getStateFromMeta(0), 3);
		world.setBlockState(new BlockPos(i + 8, j + 6, k + 14), Block.getBlockById(5).getStateFromMeta(0), 3);
		world.setBlockState(new BlockPos(i + 9, j + 6, k + 14), Block.getBlockById(5).getStateFromMeta(0), 3);
		world.setBlockState(new BlockPos(i + 10, j + 6, k + 14), Block.getBlockById(5).getStateFromMeta(0), 3);
		world.setBlockState(new BlockPos(i + 11, j + 6, k + 14), Block.getBlockById(5).getStateFromMeta(0), 3);
		world.setBlockState(new BlockPos(i + 12, j + 6, k + 14), Block.getBlockById(5).getStateFromMeta(0), 3);
		world.setBlockState(new BlockPos(i + 13, j + 6, k + 14), Block.getBlockById(17).getStateFromMeta(9), 3);
		world.setBlockState(new BlockPos(i + 0, j + 6, k + 15), Block.getBlockById(17).getStateFromMeta(5), 3);
		world.setBlockState(new BlockPos(i + 1, j + 6, k + 15), Block.getBlockById(5).getStateFromMeta(0), 3);
		world.setBlockState(new BlockPos(i + 2, j + 6, k + 15), Block.getBlockById(5).getStateFromMeta(0), 3);
		world.setBlockState(new BlockPos(i + 3, j + 6, k + 15), Block.getBlockById(5).getStateFromMeta(0), 3);
		world.setBlockState(new BlockPos(i + 4, j + 6, k + 15), Block.getBlockById(5).getStateFromMeta(0), 3);
		world.setBlockState(new BlockPos(i + 5, j + 6, k + 15), Block.getBlockById(17).getStateFromMeta(9), 3);
		world.setBlockState(new BlockPos(i + 6, j + 6, k + 15), Block.getBlockById(5).getStateFromMeta(0), 3);
		world.setBlockState(new BlockPos(i + 7, j + 6, k + 15), Block.getBlockById(5).getStateFromMeta(0), 3);
		world.setBlockState(new BlockPos(i + 8, j + 6, k + 15), Block.getBlockById(17).getStateFromMeta(9), 3);
		world.setBlockState(new BlockPos(i + 9, j + 6, k + 15), Block.getBlockById(5).getStateFromMeta(0), 3);
		world.setBlockState(new BlockPos(i + 10, j + 6, k + 15), Block.getBlockById(5).getStateFromMeta(0), 3);
		world.setBlockState(new BlockPos(i + 11, j + 6, k + 15), Block.getBlockById(5).getStateFromMeta(0), 3);
		world.setBlockState(new BlockPos(i + 12, j + 6, k + 15), Block.getBlockById(5).getStateFromMeta(0), 3);
		world.setBlockState(new BlockPos(i + 13, j + 6, k + 15), Block.getBlockById(17).getStateFromMeta(9), 3);
		world.setBlockState(new BlockPos(i + 0, j + 6, k + 16), Block.getBlockById(17).getStateFromMeta(5), 3);
		world.setBlockState(new BlockPos(i + 1, j + 6, k + 16), Block.getBlockById(5).getStateFromMeta(0), 3);
		world.setBlockState(new BlockPos(i + 2, j + 6, k + 16), Block.getBlockById(5).getStateFromMeta(0), 3);
		world.setBlockState(new BlockPos(i + 3, j + 6, k + 16), Block.getBlockById(5).getStateFromMeta(0), 3);
		world.setBlockState(new BlockPos(i + 4, j + 6, k + 16), Block.getBlockById(5).getStateFromMeta(0), 3);
		world.setBlockState(new BlockPos(i + 5, j + 6, k + 16), Block.getBlockById(5).getStateFromMeta(0), 3);
		world.setBlockState(new BlockPos(i + 6, j + 6, k + 16), Block.getBlockById(5).getStateFromMeta(0), 3);
		world.setBlockState(new BlockPos(i + 7, j + 6, k + 16), Block.getBlockById(5).getStateFromMeta(0), 3);
		world.setBlockState(new BlockPos(i + 8, j + 6, k + 16), Block.getBlockById(5).getStateFromMeta(0), 3);
		world.setBlockState(new BlockPos(i + 9, j + 6, k + 16), Block.getBlockById(5).getStateFromMeta(0), 3);
		world.setBlockState(new BlockPos(i + 10, j + 6, k + 16), Block.getBlockById(5).getStateFromMeta(0), 3);
		world.setBlockState(new BlockPos(i + 11, j + 6, k + 16), Block.getBlockById(5).getStateFromMeta(0), 3);
		world.setBlockState(new BlockPos(i + 12, j + 6, k + 16), Block.getBlockById(5).getStateFromMeta(0), 3);
		world.setBlockState(new BlockPos(i + 13, j + 6, k + 16), Block.getBlockById(17).getStateFromMeta(9), 3);
		world.setBlockState(new BlockPos(i + 15, j + 6, k + 16), Block.getBlockById(188).getStateFromMeta(0), 3);
		world.setBlockState(new BlockPos(i + 1, j + 6, k + 17), Block.getBlockById(17).getStateFromMeta(9), 3);
		world.setBlockState(new BlockPos(i + 2, j + 6, k + 17), Block.getBlockById(17).getStateFromMeta(5), 3);
		world.setBlockState(new BlockPos(i + 3, j + 6, k + 17), Block.getBlockById(17).getStateFromMeta(5), 3);
		world.setBlockState(new BlockPos(i + 4, j + 6, k + 17), Block.getBlockById(17).getStateFromMeta(5), 3);
		world.setBlockState(new BlockPos(i + 5, j + 6, k + 17), Block.getBlockById(17).getStateFromMeta(5), 3);
		world.setBlockState(new BlockPos(i + 6, j + 6, k + 17), Block.getBlockById(17).getStateFromMeta(5), 3);
		world.setBlockState(new BlockPos(i + 7, j + 6, k + 17), Block.getBlockById(17).getStateFromMeta(5), 3);
		world.setBlockState(new BlockPos(i + 8, j + 6, k + 17), Block.getBlockById(17).getStateFromMeta(5), 3);
		world.setBlockState(new BlockPos(i + 9, j + 6, k + 17), Block.getBlockById(17).getStateFromMeta(5), 3);
		world.setBlockState(new BlockPos(i + 10, j + 6, k + 17), Block.getBlockById(17).getStateFromMeta(5), 3);
		world.setBlockState(new BlockPos(i + 11, j + 6, k + 17), Block.getBlockById(17).getStateFromMeta(5), 3);
		world.setBlockState(new BlockPos(i + 12, j + 6, k + 17), Block.getBlockById(17).getStateFromMeta(5), 3);
		world.setBlockState(new BlockPos(i + 13, j + 6, k + 17), Block.getBlockById(17).getStateFromMeta(9), 3);
		world.setBlockState(new BlockPos(i + 15, j + 6, k + 17), Block.getBlockById(188).getStateFromMeta(0), 3);
		world.setBlockState(new BlockPos(i + 4, j + 6, k + 18), Block.getBlockById(188).getStateFromMeta(0), 3);
		world.setBlockState(new BlockPos(i + 15, j + 6, k + 18), Block.getBlockById(188).getStateFromMeta(0), 3);
		world.setBlockState(new BlockPos(i + 4, j + 6, k + 19), Block.getBlockById(188).getStateFromMeta(0), 3);
		world.setBlockState(new BlockPos(i + 5, j + 6, k + 19), Block.getBlockById(188).getStateFromMeta(0), 3);
		world.setBlockState(new BlockPos(i + 14, j + 6, k + 19), Block.getBlockById(188).getStateFromMeta(0), 3);
		world.setBlockState(new BlockPos(i + 15, j + 6, k + 19), Block.getBlockById(188).getStateFromMeta(0), 3);
		world.setBlockState(new BlockPos(i + 5, j + 6, k + 20), Block.getBlockById(188).getStateFromMeta(0), 3);
		world.setBlockState(new BlockPos(i + 6, j + 6, k + 20), Block.getBlockById(188).getStateFromMeta(0), 3);
		world.setBlockState(new BlockPos(i + 13, j + 6, k + 20), Block.getBlockById(188).getStateFromMeta(0), 3);
		world.setBlockState(new BlockPos(i + 14, j + 6, k + 20), Block.getBlockById(188).getStateFromMeta(0), 3);
		world.setBlockState(new BlockPos(i + 6, j + 6, k + 21), Block.getBlockById(188).getStateFromMeta(0), 3);
		world.setBlockState(new BlockPos(i + 7, j + 6, k + 21), Block.getBlockById(188).getStateFromMeta(0), 3);
		world.setBlockState(new BlockPos(i + 12, j + 6, k + 21), Block.getBlockById(188).getStateFromMeta(0), 3);
		world.setBlockState(new BlockPos(i + 13, j + 6, k + 21), Block.getBlockById(188).getStateFromMeta(0), 3);
		world.setBlockState(new BlockPos(i + 7, j + 6, k + 22), Block.getBlockById(188).getStateFromMeta(0), 3);
		world.setBlockState(new BlockPos(i + 8, j + 6, k + 22), Block.getBlockById(188).getStateFromMeta(0), 3);
		world.setBlockState(new BlockPos(i + 11, j + 6, k + 22), Block.getBlockById(188).getStateFromMeta(0), 3);
		world.setBlockState(new BlockPos(i + 12, j + 6, k + 22), Block.getBlockById(188).getStateFromMeta(0), 3);
		world.setBlockState(new BlockPos(i + 8, j + 6, k + 23), Block.getBlockById(188).getStateFromMeta(0), 3);
		world.setBlockState(new BlockPos(i + 9, j + 6, k + 23), Block.getBlockById(188).getStateFromMeta(0), 3);
		world.setBlockState(new BlockPos(i + 10, j + 6, k + 23), Block.getBlockById(188).getStateFromMeta(0), 3);
		world.setBlockState(new BlockPos(i + 11, j + 6, k + 23), Block.getBlockById(188).getStateFromMeta(0), 3);
		world.setBlockState(new BlockPos(i + 5, j + 7, k + 0), Block.getBlockById(17).getStateFromMeta(9), 3);
		world.setBlockState(new BlockPos(i + 6, j + 7, k + 0), Block.getBlockById(17).getStateFromMeta(9), 3);
		world.setBlockState(new BlockPos(i + 7, j + 7, k + 0), Block.getBlockById(17).getStateFromMeta(9), 3);
		world.setBlockState(new BlockPos(i + 8, j + 7, k + 0), Block.getBlockById(17).getStateFromMeta(9), 3);
		world.setBlockState(new BlockPos(i + 9, j + 7, k + 0), Block.getBlockById(17).getStateFromMeta(9), 3);
		world.setBlockState(new BlockPos(i + 10, j + 7, k + 0), Block.getBlockById(17).getStateFromMeta(9), 3);
		world.setBlockState(new BlockPos(i + 11, j + 7, k + 0), Block.getBlockById(17).getStateFromMeta(9), 3);
		world.setBlockState(new BlockPos(i + 12, j + 7, k + 0), Block.getBlockById(17).getStateFromMeta(9), 3);
		world.setBlockState(new BlockPos(i + 13, j + 7, k + 0), Block.getBlockById(17).getStateFromMeta(9), 3);
		world.setBlockState(new BlockPos(i + 4, j + 7, k + 1), Block.getBlockById(17).getStateFromMeta(9), 3);
		world.setBlockState(new BlockPos(i + 5, j + 7, k + 1), Block.getBlockById(5).getStateFromMeta(0), 3);
		world.setBlockState(new BlockPos(i + 6, j + 7, k + 1), Block.getBlockById(5).getStateFromMeta(0), 3);
		world.setBlockState(new BlockPos(i + 7, j + 7, k + 1), Block.getBlockById(5).getStateFromMeta(0), 3);
		world.setBlockState(new BlockPos(i + 8, j + 7, k + 1), Block.getBlockById(5).getStateFromMeta(0), 3);
		world.setBlockState(new BlockPos(i + 9, j + 7, k + 1), Block.getBlockById(5).getStateFromMeta(0), 3);
		world.setBlockState(new BlockPos(i + 10, j + 7, k + 1), Block.getBlockById(5).getStateFromMeta(0), 3);
		world.setBlockState(new BlockPos(i + 11, j + 7, k + 1), Block.getBlockById(5).getStateFromMeta(0), 3);
		world.setBlockState(new BlockPos(i + 12, j + 7, k + 1), Block.getBlockById(5).getStateFromMeta(0), 3);
		world.setBlockState(new BlockPos(i + 13, j + 7, k + 1), Block.getBlockById(5).getStateFromMeta(0), 3);
		world.setBlockState(new BlockPos(i + 14, j + 7, k + 1), Block.getBlockById(17).getStateFromMeta(9), 3);
		world.setBlockState(new BlockPos(i + 1, j + 7, k + 2), Block.getBlockById(17).getStateFromMeta(9), 3);
		world.setBlockState(new BlockPos(i + 2, j + 7, k + 2), Block.getBlockById(17).getStateFromMeta(9), 3);
		world.setBlockState(new BlockPos(i + 3, j + 7, k + 2), Block.getBlockById(17).getStateFromMeta(9), 3);
		world.setBlockState(new BlockPos(i + 4, j + 7, k + 2), Block.getBlockById(5).getStateFromMeta(0), 3);
		world.setBlockState(new BlockPos(i + 5, j + 7, k + 2), Block.getBlockById(5).getStateFromMeta(0), 3);
		world.setBlockState(new BlockPos(i + 6, j + 7, k + 2), Block.getBlockById(5).getStateFromMeta(0), 3);
		world.setBlockState(new BlockPos(i + 7, j + 7, k + 2), Block.getBlockById(5).getStateFromMeta(0), 3);
		world.setBlockState(new BlockPos(i + 8, j + 7, k + 2), Block.getBlockById(5).getStateFromMeta(0), 3);
		world.setBlockState(new BlockPos(i + 9, j + 7, k + 2), Block.getBlockById(5).getStateFromMeta(0), 3);
		world.setBlockState(new BlockPos(i + 10, j + 7, k + 2), Block.getBlockById(5).getStateFromMeta(0), 3);
		world.setBlockState(new BlockPos(i + 11, j + 7, k + 2), Block.getBlockById(5).getStateFromMeta(0), 3);
		world.setBlockState(new BlockPos(i + 12, j + 7, k + 2), Block.getBlockById(65).getStateFromMeta(3), 3);
		world.setBlockState(new BlockPos(i + 13, j + 7, k + 2), Block.getBlockById(5).getStateFromMeta(0), 3);
		world.setBlockState(new BlockPos(i + 14, j + 7, k + 2), Block.getBlockById(17).getStateFromMeta(9), 3);
		world.setBlockState(new BlockPos(i + 15, j + 7, k + 2), Block.getBlockById(17).getStateFromMeta(9), 3);
		world.setBlockState(new BlockPos(i + 0, j + 7, k + 3), Block.getBlockById(17).getStateFromMeta(5), 3);
		world.setBlockState(new BlockPos(i + 1, j + 7, k + 3), Block.getBlockById(5).getStateFromMeta(0), 3);
		world.setBlockState(new BlockPos(i + 2, j + 7, k + 3), Block.getBlockById(5).getStateFromMeta(0), 3);
		world.setBlockState(new BlockPos(i + 3, j + 7, k + 3), Block.getBlockById(5).getStateFromMeta(0), 3);
		world.setBlockState(new BlockPos(i + 4, j + 7, k + 3), Block.getBlockById(5).getStateFromMeta(0), 3);
		world.setBlockState(new BlockPos(i + 5, j + 7, k + 3), Block.getBlockById(5).getStateFromMeta(0), 3);
		world.setBlockState(new BlockPos(i + 6, j + 7, k + 3), Block.getBlockById(5).getStateFromMeta(0), 3);
		world.setBlockState(new BlockPos(i + 7, j + 7, k + 3), Block.getBlockById(5).getStateFromMeta(0), 3);
		world.setBlockState(new BlockPos(i + 8, j + 7, k + 3), Block.getBlockById(5).getStateFromMeta(0), 3);
		world.setBlockState(new BlockPos(i + 9, j + 7, k + 3), Block.getBlockById(5).getStateFromMeta(0), 3);
		world.setBlockState(new BlockPos(i + 10, j + 7, k + 3), Block.getBlockById(5).getStateFromMeta(0), 3);
		world.setBlockState(new BlockPos(i + 11, j + 7, k + 3), Block.getBlockById(5).getStateFromMeta(0), 3);
		world.setBlockState(new BlockPos(i + 12, j + 7, k + 3), Block.getBlockById(5).getStateFromMeta(0), 3);
		world.setBlockState(new BlockPos(i + 13, j + 7, k + 3), Block.getBlockById(17).getStateFromMeta(9), 3);
		world.setBlockState(new BlockPos(i + 15, j + 7, k + 3), Block.getBlockById(188).getStateFromMeta(0), 3);
		world.setBlockState(new BlockPos(i + 0, j + 7, k + 4), Block.getBlockById(17).getStateFromMeta(5), 3);
		world.setBlockState(new BlockPos(i + 1, j + 7, k + 4), Block.getBlockById(5).getStateFromMeta(0), 3);
		world.setBlockState(new BlockPos(i + 2, j + 7, k + 4), Block.getBlockById(5).getStateFromMeta(0), 3);
		world.setBlockState(new BlockPos(i + 3, j + 7, k + 4), Block.getBlockById(5).getStateFromMeta(0), 3);
		world.setBlockState(new BlockPos(i + 4, j + 7, k + 4), Block.getBlockById(5).getStateFromMeta(0), 3);
		world.setBlockState(new BlockPos(i + 5, j + 7, k + 4), Block.getBlockById(5).getStateFromMeta(0), 3);
		world.setBlockState(new BlockPos(i + 6, j + 7, k + 4), Block.getBlockById(17).getStateFromMeta(9), 3);
		world.setBlockState(new BlockPos(i + 7, j + 7, k + 4), Block.getBlockById(5).getStateFromMeta(0), 3);
		world.setBlockState(new BlockPos(i + 8, j + 7, k + 4), Block.getBlockById(5).getStateFromMeta(0), 3);
		world.setBlockState(new BlockPos(i + 9, j + 7, k + 4), Block.getBlockById(17).getStateFromMeta(9), 3);
		world.setBlockState(new BlockPos(i + 10, j + 7, k + 4), Block.getBlockById(5).getStateFromMeta(0), 3);
		world.setBlockState(new BlockPos(i + 11, j + 7, k + 4), Block.getBlockById(5).getStateFromMeta(0), 3);
		world.setBlockState(new BlockPos(i + 12, j + 7, k + 4), Block.getBlockById(5).getStateFromMeta(0), 3);
		world.setBlockState(new BlockPos(i + 13, j + 7, k + 4), Block.getBlockById(17).getStateFromMeta(9), 3);
		world.setBlockState(new BlockPos(i + 15, j + 7, k + 4), Block.getBlockById(188).getStateFromMeta(0), 3);
		world.setBlockState(new BlockPos(i + 0, j + 7, k + 5), Block.getBlockById(17).getStateFromMeta(5), 3);
		world.setBlockState(new BlockPos(i + 1, j + 7, k + 5), Block.getBlockById(5).getStateFromMeta(0), 3);
		world.setBlockState(new BlockPos(i + 2, j + 7, k + 5), Block.getBlockById(5).getStateFromMeta(0), 3);
		world.setBlockState(new BlockPos(i + 3, j + 7, k + 5), Block.getBlockById(5).getStateFromMeta(0), 3);
		world.setBlockState(new BlockPos(i + 4, j + 7, k + 5), Block.getBlockById(5).getStateFromMeta(0), 3);
		world.setBlockState(new BlockPos(i + 5, j + 7, k + 5), Block.getBlockById(5).getStateFromMeta(0), 3);
		world.setBlockState(new BlockPos(i + 6, j + 7, k + 5), Block.getBlockById(5).getStateFromMeta(0), 3);
		world.setBlockState(new BlockPos(i + 9, j + 7, k + 5), Block.getBlockById(5).getStateFromMeta(0), 3);
		world.setBlockState(new BlockPos(i + 10, j + 7, k + 5), Block.getBlockById(5).getStateFromMeta(0), 3);
		world.setBlockState(new BlockPos(i + 11, j + 7, k + 5), Block.getBlockById(5).getStateFromMeta(0), 3);
		world.setBlockState(new BlockPos(i + 12, j + 7, k + 5), Block.getBlockById(5).getStateFromMeta(0), 3);
		world.setBlockState(new BlockPos(i + 13, j + 7, k + 5), Block.getBlockById(17).getStateFromMeta(9), 3);
		world.setBlockState(new BlockPos(i + 15, j + 7, k + 5), Block.getBlockById(188).getStateFromMeta(0), 3);
		world.setBlockState(new BlockPos(i + 0, j + 7, k + 6), Block.getBlockById(17).getStateFromMeta(5), 3);
		world.setBlockState(new BlockPos(i + 1, j + 7, k + 6), Block.getBlockById(5).getStateFromMeta(0), 3);
		world.setBlockState(new BlockPos(i + 2, j + 7, k + 6), Block.getBlockById(5).getStateFromMeta(0), 3);
		world.setBlockState(new BlockPos(i + 3, j + 7, k + 6), Block.getBlockById(5).getStateFromMeta(0), 3);
		world.setBlockState(new BlockPos(i + 4, j + 7, k + 6), Block.getBlockById(5).getStateFromMeta(0), 3);
		world.setBlockState(new BlockPos(i + 5, j + 7, k + 6), Block.getBlockById(5).getStateFromMeta(0), 3);
		world.setBlockState(new BlockPos(i + 6, j + 7, k + 6), Block.getBlockById(5).getStateFromMeta(0), 3);
		world.setBlockState(new BlockPos(i + 9, j + 7, k + 6), Block.getBlockById(5).getStateFromMeta(0), 3);
		world.setBlockState(new BlockPos(i + 10, j + 7, k + 6), Block.getBlockById(5).getStateFromMeta(0), 3);
		world.setBlockState(new BlockPos(i + 11, j + 7, k + 6), Block.getBlockById(5).getStateFromMeta(0), 3);
		world.setBlockState(new BlockPos(i + 12, j + 7, k + 6), Block.getBlockById(5).getStateFromMeta(0), 3);
		world.setBlockState(new BlockPos(i + 13, j + 7, k + 6), Block.getBlockById(17).getStateFromMeta(9), 3);
		world.setBlockState(new BlockPos(i + 0, j + 7, k + 7), Block.getBlockById(17).getStateFromMeta(5), 3);
		world.setBlockState(new BlockPos(i + 1, j + 7, k + 7), Block.getBlockById(5).getStateFromMeta(0), 3);
		world.setBlockState(new BlockPos(i + 2, j + 7, k + 7), Block.getBlockById(5).getStateFromMeta(0), 3);
		world.setBlockState(new BlockPos(i + 3, j + 7, k + 7), Block.getBlockById(5).getStateFromMeta(0), 3);
		world.setBlockState(new BlockPos(i + 4, j + 7, k + 7), Block.getBlockById(5).getStateFromMeta(0), 3);
		world.setBlockState(new BlockPos(i + 5, j + 7, k + 7), Block.getBlockById(5).getStateFromMeta(0), 3);
		world.setBlockState(new BlockPos(i + 6, j + 7, k + 7), Block.getBlockById(17).getStateFromMeta(9), 3);
		world.setBlockState(new BlockPos(i + 7, j + 7, k + 7), Block.getBlockById(5).getStateFromMeta(0), 3);
		world.setBlockState(new BlockPos(i + 8, j + 7, k + 7), Block.getBlockById(5).getStateFromMeta(0), 3);
